Workbook

Sheet Metode
A1: METODE PENYELARASAN DATA PRODUKSI TERHADAP WELL TEST (MULTIPLIER)
A3: Rumus
A4: 1 | B4: Titik koreksi = bulan yang punya data WT dan Prod > 0. Multiplier = WT / Prod, dan Prod Koreksi = WT pada bulan itu.
A5: 2 | B5: Pada bulan tanpa WT, multiplier dari titik koreksi terakhir dibawa maju dan dikalikan ke Prod. Contoh: Jan 90->100 (x1,1111); Feb 85 -> 94,4; Mar 90 -> 100; Apr 80 -> 95 (x1,1875).
A6: 3 | B6: Tidak ada batas minimum/maksimum multiplier; nilai disajikan apa adanya.
A7: 4 | B7: Metode dijalankan terpisah untuk Oil, Gas, Water, dan Fluid (masing-masing memakai WT dan multipliernya sendiri).
A9: Aturan kasus khusus
A10: 5 | B10: WT ada tetapi Prod = 0: Prod Koreksi = 0 (berapapun multiplier-nya). Multiplier tidak dihitung ulang, nilai sebelumnya dilanjutkan.
A11: 6 | B11: WT = 0 sementara Prod > 0: Prod Koreksi bulan itu = 0 (multiplier = 0). Bulan berikutnya yang tidak punya WT dibiarkan apa adanya (multiplier kembali 1, Prod Koreksi = Prod) sampai ada WT berikutnya.
A12: 7 | B12: Bulan sebelum WT pertama sebuah sumur: multiplier = 1 (tidak dikoreksi), karena belum ada informasi WT.
A13: 8 | B13: Bulan tanpa data produksi (mis. setelah Apr-2025, hanya ada WT): Prod Koreksi dikosongkan. WT tetap tampil di grafik.
A14: 9 | B14: WT per bulan = rata-rata sederhana test valid pada bulan tsb, diambil apa adanya dari sheet Rekap file sumber.
A15: 10 | B15: Fluid terkoreksi dihitung dengan multiplier Fluid sendiri, sehingga tepat mengikuti WT Fluid. Akibatnya Fluid terkoreksi tidak selalu sama persis dengan Oil terkoreksi + Water terkoreksi.
A16: 11 | B16: KKNB-1: Oil prod dan WT bernilai 0 di semua bulan, sehingga multiplier Oil = 1 dan tidak ada koreksi Oil.
A17: 12 | B17: Sumbu waktu grafik = tanggal minimum dan maksimum data prod/WT tiap sumur; sumbu Y sama pada grafik sebelum dan sesudah (nilai ditetapkan saat file dibuat).
A19: Konvensi
A20: 13 | B20: Font biru = input/sumber; hitam = rumus. Kumulatif = rate x jumlah hari per bulan (Oil, Water, Fluid: MBbl; Gas: MMscf).
A21: 14 | B21: Sumber data: sheet Rekap pada Rekap_Produksi_WellTest_KKA_KKNA_KKNB.xlsx (produksi = FS Claim; WT = rata-rata test valid per bulan).

Sheet Ringkasan
A1: RINGKASAN PER SUMUR: SEBELUM vs SESUDAH KOREKSI
A2: Semua angka dihitung dari sheet Koreksi_Data. Kumulatif = rate x hari per bulan.
A4: OIL (BOPD) | kumulatif dalam MBbl
A5: Sumur | B5: Awal data | C5: Akhir data | D5: Bulan Prod | E5: Bulan WT | F5: Titik koreksi | G5: Multiplier min | H5: Multiplier maks | I5: Multiplier rata-rata | J5: Multiplier terakhir | K5: Kum. Sebelum | L5: Kum. Sesudah | M5: Selisih (%) | N5: Prod/WT sebelum (bulan WT)
A6: KKA-1 | B6: =_xlfn.MINIFS(Koreksi_Data!$C$7:$C$2719,Koreksi_Data!$B$7:$B$2719,$A6) -> 37438 | C6: =_xlfn.MAXIFS(Koreksi_Data!$C$7:$C$2719,Koreksi_Data!$B$7:$B$2719,$A6) -> 46266 | D6: =COUNTIFS(Koreksi_Data!$B$7:$B$2719,$A6,Koreksi_Data!$D$7:$D$2719,">=0") -> 272 | E6: =COUNTIFS(Koreksi_Data!$B$7:$B$2719,$A6,Koreksi_Data!$E$7:$E$2719,">=0") -> 152 | F6: =SUMPRODUCT((Koreksi_Data!$B$7:$B$2719=$A6)*ISNUMBER(Koreksi_Data!$E$7:$E$2719)*(Koreksi_Data!$D$7:$D$2719>0)) -> 133 | G6: =IFERROR(_xlfn.MINIFS(Koreksi_Data!$F$7:$F$2719,Koreksi_Data!$B$7:$B$2719,$A6,Koreksi_Data!$D$7:$D$2719,">=0"),"-") -> 0 | H6: =IFERROR(_xlfn.MAXIFS(Koreksi_Data!$F$7:$F$2719,Koreksi_Data!$B$7:$B$2719,$A6,Koreksi_Data!$D$7:$D$2719,">=0"),"-") -> 6 | I6: =IFERROR(AVERAGEIFS(Koreksi_Data!$F$7:$F$2719,Koreksi_Data!$B$7:$B$2719,$A6,Koreksi_Data!$D$7:$D$2719,">=0"),"-") -> 1.2950435 | J6: =INDEX(Koreksi_Data!$F$7:$F$2719,MATCH($A6,Koreksi_Data!$B$7:$B$2719,0)+COUNTIF(Koreksi_Data!$B$7:$B$2719,$A6)-1) -> 1.2794118 | K6: =SUMPRODUCT((Koreksi_Data!$B$7:$B$2719=$A6)*Koreksi_Data!$D$7:$D$2719*Koreksi_Data!$T$7:$T$2719)/1000 -> 978.1446 | L6: =SUMPRODUCT((Koreksi_Data!$B$7:$B$2719=$A6)*Koreksi_Data!$G$7:$G$2719*Koreksi_Data!$T$7:$T$2719)/1000 -> 1249.4641 | M6: =IF(K6=0,"-",L6/K6-1) -> 0.2773818 | N6: =IFERROR(SUMPRODUCT((Koreksi_Data!$B$7:$B$2719=$A6)*ISNUMBER(Koreksi_Data!$E$7:$E$2719)*Koreksi_Data!$D$7:$D$2719)/SUMPRODUCT((Koreksi_Data!$B$7:$B$2719=$A6)*ISNUMBER(Koreksi_Data!$D$7:$D$2719)*Koreksi_Data!$E$7:$E$2719),"-") -> 0.76907239
A7: KKA-2ST2L | B7: =_xlfn.MINIFS(Koreksi_Data!$C$7:$C$2719,Koreksi_Data!$B$7:$B$2719,$A7) -> 39814 | C7: =_xlfn.MAXIFS(Koreksi_Data!$C$7:$C$2719,Koreksi_Data!$B$7:$B$2719,$A7) -> 42856 | D7: =COUNTIFS(Koreksi_Data!$B$7:$B$2719,$A7,Koreksi_Data!$D$7:$D$2719,">=0") -> 90 | E7: =COUNTIFS(Koreksi_Data!$B$7:$B$2719,$A7,Koreksi_Data!$E$7:$E$2719,">=0") -> 22 | F7: =SUMPRODUCT((Koreksi_Data!$B$7:$B$2719=$A7)*ISNUMBER(Koreksi_Data!$E$7:$E$2719)*(Koreksi_Data!$D$7:$D$2719>0)) -> 19 | G7: =IFERROR(_xlfn.MINIFS(Koreksi_Data!$F$7:$F$2719,Koreksi_Data!$B$7:$B$2719,$A7,Koreksi_Data!$D$7:$D$2719,">=0"),"-") -> 0 | H7: =IFERROR(_xlfn.MAXIFS(Koreksi_Data!$F$7:$F$2719,Koreksi_Data!$B$7:$B$2719,$A7,Koreksi_Data!$D$7:$D$2719,">=0"),"-") -> 1.8929577 | I7: =IFERROR(AVERAGEIFS(Koreksi_Data!$F$7:$F$2719,Koreksi_Data!$B$7:$B$2719,$A7,Koreksi_Data!$D$7:$D$2719,">=0"),"-") -> 1.0286329 | J7: =INDEX(Koreksi_Data!$F$7:$F$2719,MATCH($A7,Koreksi_Data!$B$7:$B$2719,0)+COUNTIF(Koreksi_Data!$B$7:$B$2719,$A7)-1) -> 1 | K7: =SUMPRODUCT((Koreksi_Data!$B$7:$B$2719=$A7)*Koreksi_Data!$D$7:$D$2719*Koreksi_Data!$T$7:$T$2719)/1000 -> 604.1113 | L7: =SUMPRODUCT((Koreksi_Data!$B$7:$B$2719=$A7)*Koreksi_Data!$G$7:$G$2719*Koreksi_Data!$T$7:$T$2719)/1000 -> 715.31982 | M7: =IF(K7=0,"-",L7/K7-1) -> 0.18408615 | N7: =IFERROR(SUMPRODUCT((Koreksi_Data!$B$7:$B$2719=$A7)*ISNUMBER(Koreksi_Data!$E$7:$E$2719)*Koreksi_Data!$D$7:$D$2719)/SUMPRODUCT((Koreksi_Data!$B$7:$B$2719=$A7)*ISNUMBER(Koreksi_Data!$D$7:$D$2719)*Koreksi_Data!$E$7:$E$2719),"-") -> 0.92052383
A8: KKA-3 | B8: =_xlfn.MINIFS(Koreksi_Data!$C$7:$C$2719,Koreksi_Data!$B$7:$B$2719,$A8) -> 39845 | C8: =_xlfn.MAXIFS(Koreksi_Data!$C$7:$C$2719,Koreksi_Data!$B$7:$B$2719,$A8) -> 46266 | D8: =COUNTIFS(Koreksi_Data!$B$7:$B$2719,$A8,Koreksi_Data!$D$7:$D$2719,">=0") -> 193 | E8: =COUNTIFS(Koreksi_Data!$B$7:$B$2719,$A8,Koreksi_Data!$E$7:$E$2719,">=0") -> 78 | F8: =SUMPRODUCT((Koreksi_Data!$B$7:$B$2719=$A8)*ISNUMBER(Koreksi_Data!$E$7:$E$2719)*(Koreksi_Data!$D$7:$D$2719>0)) -> 34 | G8: =IFERROR(_xlfn.MINIFS(Koreksi_Data!$F$7:$F$2719,Koreksi_Data!$B$7:$B$2719,$A8,Koreksi_Data!$D$7:$D$2719,">=0"),"-") -> 0 | H8: =IFERROR(_xlfn.MAXIFS(Koreksi_Data!$F$7:$F$2719,Koreksi_Data!$B$7:$B$2719,$A8,Koreksi_Data!$D$7:$D$2719,">=0"),"-") -> 4.7706422 | I8: =IFERROR(AVERAGEIFS(Koreksi_Data!$F$7:$F$2719,Koreksi_Data!$B$7:$B$2719,$A8,Koreksi_Data!$D$7:$D$2719,">=0"),"-") -> 1.0192703 | J8: =INDEX(Koreksi_Data!$F$7:$F$2719,MATCH($A8,Koreksi_Data!$B$7:$B$2719,0)+COUNTIF(Koreksi_Data!$B$7:$B$2719,$A8)-1) -> 3.0181087 | K8: =SUMPRODUCT((Koreksi_Data!$B$7:$B$2719=$A8)*Koreksi_Data!$D$7:$D$2719*Koreksi_Data!$T$7:$T$2719)/1000 -> 55.621414 | L8: =SUMPRODUCT((Koreksi_Data!$B$7:$B$2719=$A8)*Koreksi_Data!$G$7:$G$2719*Koreksi_Data!$T$7:$T$2719)/1000 -> 64.983339 | M8: =IF(K8=0,"-",L8/K8-1) -> 0.16831512 | N8: =IFERROR(SUMPRODUCT((Koreksi_Data!$B$7:$B$2719=$A8)*ISNUMBER(Koreksi_Data!$E$7:$E$2719)*Koreksi_Data!$D$7:$D$2719)/SUMPRODUCT((Koreksi_Data!$B$7:$B$2719=$A8)*ISNUMBER(Koreksi_Data!$D$7:$D$2719)*Koreksi_Data!$E$7:$E$2719),"-") -> 0.59719452
A9: KKA-4 | B9: =_xlfn.MINIFS(Koreksi_Data!$C$7:$C$2719,Koreksi_Data!$B$7:$B$2719,$A9) -> 40210 | C9: =_xlfn.MAXIFS(Koreksi_Data!$C$7:$C$2719,Koreksi_Data!$B$7:$B$2719,$A9) -> 46113 | D9: =COUNTIFS(Koreksi_Data!$B$7:$B$2719,$A9,Koreksi_Data!$D$7:$D$2719,">=0") -> 172 | E9: =COUNTIFS(Koreksi_Data!$B$7:$B$2719,$A9,Koreksi_Data!$E$7:$E$2719,">=0") -> 92 | F9: =SUMPRODUCT((Koreksi_Data!$B$7:$B$2719=$A9)*ISNUMBER(Koreksi_Data!$E$7:$E$2719)*(Koreksi_Data!$D$7:$D$2719>0)) -> 81 | G9: =IFERROR(_xlfn.MINIFS(Koreksi_Data!$F$7:$F$2719,Koreksi_Data!$B$7:$B$2719,$A9,Koreksi_Data!$D$7:$D$2719,">=0"),"-") -> 0 | H9: =IFERROR(_xlfn.MAXIFS(Koreksi_Data!$F$7:$F$2719,Koreksi_Data!$B$7:$B$2719,$A9,Koreksi_Data!$D$7:$D$2719,">=0"),"-") -> 4.8752834 | I9: =IFERROR(AVERAGEIFS(Koreksi_Data!$F$7:$F$2719,Koreksi_Data!$B$7:$B$2719,$A9,Koreksi_Data!$D$7:$D$2719,">=0"),"-") -> 1.3359286 | J9: =INDEX(Koreksi_Data!$F$7:$F$2719,MATCH($A9,Koreksi_Data!$B$7:$B$2719,0)+COUNTIF(Koreksi_Data!$B$7:$B$2719,$A9)-1) -> 1.3740458 | K9: =SUMPRODUCT((Koreksi_Data!$B$7:$B$2719=$A9)*Koreksi_Data!$D$7:$D$2719*Koreksi_Data!$T$7:$T$2719)/1000 -> 371.99164 | L9: =SUMPRODUCT((Koreksi_Data!$B$7:$B$2719=$A9)*Koreksi_Data!$G$7:$G$2719*Koreksi_Data!$T$7:$T$2719)/1000 -> 447.36914 | M9: =IF(K9=0,"-",L9/K9-1) -> 0.20263223 | N9: =IFERROR(SUMPRODUCT((Koreksi_Data!$B$7:$B$2719=$A9)*ISNUMBER(Koreksi_Data!$E$7:$E$2719)*Koreksi_Data!$D$7:$D$2719)/SUMPRODUCT((Koreksi_Data!$B$7:$B$2719=$A9)*ISNUMBER(Koreksi_Data!$D$7:$D$2719)*Koreksi_Data!$E$7:$E$2719),"-") -> 0.91122851
A10: KKNA-1L | B10: =_xlfn.MINIFS(Koreksi_Data!$C$7:$C$2719,Koreksi_Data!$B$7:$B$2719,$A10) -> 36161 | C10: =_xlfn.MAXIFS(Koreksi_Data!$C$7:$C$2719,Koreksi_Data!$B$7:$B$2719,$A10) -> 42430 | D10: =COUNTIFS(Koreksi_Data!$B$7:$B$2719,$A10,Koreksi_Data!$D$7:$D$2719,">=0") -> 151 | E10: =COUNTIFS(Koreksi_Data!$B$7:$B$2719,$A10,Koreksi_Data!$E$7:$E$2719,">=0") -> 59 | F10: =SUMPRODUCT((Koreksi_Data!$B$7:$B$2719=$A10)*ISNUMBER(Koreksi_Data!$E$7:$E$2719)*(Koreksi_Data!$D$7:$D$2719>0)) -> 55 | G10: =IFERROR(_xlfn.MINIFS(Koreksi_Data!$F$7:$F$2719,Koreksi_Data!$B$7:$B$2719,$A10,Koreksi_Data!$D$7:$D$2719,">=0"),"-") -> 0 | H10: =IFERROR(_xlfn.MAXIFS(Koreksi_Data!$F$7:$F$2719,Koreksi_Data!$B$7:$B$2719,$A10,Koreksi_Data!$D$7:$D$2719,">=0"),"-") -> 7.0498615 | I10: =IFERROR(AVERAGEIFS(Koreksi_Data!$F$7:$F$2719,Koreksi_Data!$B$7:$B$2719,$A10,Koreksi_Data!$D$7:$D$2719,">=0"),"-") -> 2.3476105 | J10: =INDEX(Koreksi_Data!$F$7:$F$2719,MATCH($A10,Koreksi_Data!$B$7:$B$2719,0)+COUNTIF(Koreksi_Data!$B$7:$B$2719,$A10)-1) -> 0 | K10: =SUMPRODUCT((Koreksi_Data!$B$7:$B$2719=$A10)*Koreksi_Data!$D$7:$D$2719*Koreksi_Data!$T$7:$T$2719)/1000 -> 269.91658 | L10: =SUMPRODUCT((Koreksi_Data!$B$7:$B$2719=$A10)*Koreksi_Data!$G$7:$G$2719*Koreksi_Data!$T$7:$T$2719)/1000 -> 465.53627 | M10: =IF(K10=0,"-",L10/K10-1) -> 0.72474129 | N10: =IFERROR(SUMPRODUCT((Koreksi_Data!$B$7:$B$2719=$A10)*ISNUMBER(Koreksi_Data!$E$7:$E$2719)*Koreksi_Data!$D$7:$D$2719)/SUMPRODUCT((Koreksi_Data!$B$7:$B$2719=$A10)*ISNUMBER(Koreksi_Data!$D$7:$D$2719)*Koreksi_Data!$E$7:$E$2719),"-") -> 0.56073298
A11: KKNA-1S | B11: =_xlfn.MINIFS(Koreksi_Data!$C$7:$C$2719,Koreksi_Data!$B$7:$B$2719,$A11) -> 36495 | C11: =_xlfn.MAXIFS(Koreksi_Data!$C$7:$C$2719,Koreksi_Data!$B$7:$B$2719,$A11) -> 42430 | D11: =COUNTIFS(Koreksi_Data!$B$7:$B$2719,$A11,Koreksi_Data!$D$7:$D$2719,">=0") -> 139 | E11: =COUNTIFS(Koreksi_Data!$B$7:$B$2719,$A11,Koreksi_Data!$E$7:$E$2719,">=0") -> 56 | F11: =SUMPRODUCT((Koreksi_Data!$B$7:$B$2719=$A11)*ISNUMBER(Koreksi_Data!$E$7:$E$2719)*(Koreksi_Data!$D$7:$D$2719>0)) -> 49 | G11: =IFERROR(_xlfn.MINIFS(Koreksi_Data!$F$7:$F$2719,Koreksi_Data!$B$7:$B$2719,$A11,Koreksi_Data!$D$7:$D$2719,">=0"),"-") -> 0 | H11: =IFERROR(_xlfn.MAXIFS(Koreksi_Data!$F$7:$F$2719,Koreksi_Data!$B$7:$B$2719,$A11,Koreksi_Data!$D$7:$D$2719,">=0"),"-") -> 16.718266 | I11: =IFERROR(AVERAGEIFS(Koreksi_Data!$F$7:$F$2719,Koreksi_Data!$B$7:$B$2719,$A11,Koreksi_Data!$D$7:$D$2719,">=0"),"-") -> 1.7025691 | J11: =INDEX(Koreksi_Data!$F$7:$F$2719,MATCH($A11,Koreksi_Data!$B$7:$B$2719,0)+COUNTIF(Koreksi_Data!$B$7:$B$2719,$A11)-1) -> 0.79734219 | K11: =SUMPRODUCT((Koreksi_Data!$B$7:$B$2719=$A11)*Koreksi_Data!$D$7:$D$2719*Koreksi_Data!$T$7:$T$2719)/1000 -> 112.17 | L11: =SUMPRODUCT((Koreksi_Data!$B$7:$B$2719=$A11)*Koreksi_Data!$G$7:$G$2719*Koreksi_Data!$T$7:$T$2719)/1000 -> 278.31546 | M11: =IF(K11=0,"-",L11/K11-1) -> 1.4811934 | N11: =IFERROR(SUMPRODUCT((Koreksi_Data!$B$7:$B$2719=$A11)*ISNUMBER(Koreksi_Data!$E$7:$E$2719)*Koreksi_Data!$D$7:$D$2719)/SUMPRODUCT((Koreksi_Data!$B$7:$B$2719=$A11)*ISNUMBER(Koreksi_Data!$D$7:$D$2719)*Koreksi_Data!$E$7:$E$2719),"-") -> 0.34787792
A12: KKNA-2 | B12: =_xlfn.MINIFS(Koreksi_Data!$C$7:$C$2719,Koreksi_Data!$B$7:$B$2719,$A12) -> 36161 | C12: =_xlfn.MAXIFS(Koreksi_Data!$C$7:$C$2719,Koreksi_Data!$B$7:$B$2719,$A12) -> 45505 | D12: =COUNTIFS(Koreksi_Data!$B$7:$B$2719,$A12,Koreksi_Data!$D$7:$D$2719,">=0") -> 153 | E12: =COUNTIFS(Koreksi_Data!$B$7:$B$2719,$A12,Koreksi_Data!$E$7:$E$2719,">=0") -> 54 | F12: =SUMPRODUCT((Koreksi_Data!$B$7:$B$2719=$A12)*ISNUMBER(Koreksi_Data!$E$7:$E$2719)*(Koreksi_Data!$D$7:$D$2719>0)) -> 48 | G12: =IFERROR(_xlfn.MINIFS(Koreksi_Data!$F$7:$F$2719,Koreksi_Data!$B$7:$B$2719,$A12,Koreksi_Data!$D$7:$D$2719,">=0"),"-") -> 0 | H12: =IFERROR(_xlfn.MAXIFS(Koreksi_Data!$F$7:$F$2719,Koreksi_Data!$B$7:$B$2719,$A12,Koreksi_Data!$D$7:$D$2719,">=0"),"-") -> 6.1417323 | I12: =IFERROR(AVERAGEIFS(Koreksi_Data!$F$7:$F$2719,Koreksi_Data!$B$7:$B$2719,$A12,Koreksi_Data!$D$7:$D$2719,">=0"),"-") -> 3.5687174 | J12: =INDEX(Koreksi_Data!$F$7:$F$2719,MATCH($A12,Koreksi_Data!$B$7:$B$2719,0)+COUNTIF(Koreksi_Data!$B$7:$B$2719,$A12)-1) -> 6.1417323 | K12: =SUMPRODUCT((Koreksi_Data!$B$7:$B$2719=$A12)*Koreksi_Data!$D$7:$D$2719*Koreksi_Data!$T$7:$T$2719)/1000 -> 243.67062 | L12: =SUMPRODUCT((Koreksi_Data!$B$7:$B$2719=$A12)*Koreksi_Data!$G$7:$G$2719*Koreksi_Data!$T$7:$T$2719)/1000 -> 367.85766 | M12: =IF(K12=0,"-",L12/K12-1) -> 0.50965125 | N12: =IFERROR(SUMPRODUCT((Koreksi_Data!$B$7:$B$2719=$A12)*ISNUMBER(Koreksi_Data!$E$7:$E$2719)*Koreksi_Data!$D$7:$D$2719)/SUMPRODUCT((Koreksi_Data!$B$7:$B$2719=$A12)*ISNUMBER(Koreksi_Data!$D$7:$D$2719)*Koreksi_Data!$E$7:$E$2719),"-") -> 0.78451378
A13: KKNA-3 | B13: =_xlfn.MINIFS(Koreksi_Data!$C$7:$C$2719,Koreksi_Data!$B$7:$B$2719,$A13) -> 37622 | C13: =_xlfn.MAXIFS(Koreksi_Data!$C$7:$C$2719,Koreksi_Data!$B$7:$B$2719,$A13) -> 42552 | D13: =COUNTIFS(Koreksi_Data!$B$7:$B$2719,$A13,Koreksi_Data!$D$7:$D$2719,">=0") -> 131 | E13: =COUNTIFS(Koreksi_Data!$B$7:$B$2719,$A13,Koreksi_Data!$E$7:$E$2719,">=0") -> 62 | F13: =SUMPRODUCT((Koreksi_Data!$B$7:$B$2719=$A13)*ISNUMBER(Koreksi_Data!$E$7:$E$2719)*(Koreksi_Data!$D$7:$D$2719>0)) -> 58 | G13: =IFERROR(_xlfn.MINIFS(Koreksi_Data!$F$7:$F$2719,Koreksi_Data!$B$7:$B$2719,$A13,Koreksi_Data!$D$7:$D$2719,">=0"),"-") -> 0 | H13: =IFERROR(_xlfn.MAXIFS(Koreksi_Data!$F$7:$F$2719,Koreksi_Data!$B$7:$B$2719,$A13,Koreksi_Data!$D$7:$D$2719,">=0"),"-") -> 3.3566434 | I13: =IFERROR(AVERAGEIFS(Koreksi_Data!$F$7:$F$2719,Koreksi_Data!$B$7:$B$2719,$A13,Koreksi_Data!$D$7:$D$2719,">=0"),"-") -> 1.403996 | J13: =INDEX(Koreksi_Data!$F$7:$F$2719,MATCH($A13,Koreksi_Data!$B$7:$B$2719,0)+COUNTIF(Koreksi_Data!$B$7:$B$2719,$A13)-1) -> 0.92028986 | K13: =SUMPRODUCT((Koreksi_Data!$B$7:$B$2719=$A13)*Koreksi_Data!$D$7:$D$2719*Koreksi_Data!$T$7:$T$2719)/1000 -> 565.21079 | L13: =SUMPRODUCT((Koreksi_Data!$B$7:$B$2719=$A13)*Koreksi_Data!$G$7:$G$2719*Koreksi_Data!$T$7:$T$2719)/1000 -> 819.04895 | M13: =IF(K13=0,"-",L13/K13-1) -> 0.44910352 | N13: =IFERROR(SUMPRODUCT((Koreksi_Data!$B$7:$B$2719=$A13)*ISNUMBER(Koreksi_Data!$E$7:$E$2719)*Koreksi_Data!$D$7:$D$2719)/SUMPRODUCT((Koreksi_Data!$B$7:$B$2719=$A13)*ISNUMBER(Koreksi_Data!$D$7:$D$2719)*Koreksi_Data!$E$7:$E$2719),"-") -> 0.72166437
A14: KKNA-3ST | B14: =_xlfn.MINIFS(Koreksi_Data!$C$7:$C$2719,Koreksi_Data!$B$7:$B$2719,$A14) -> 41153 | C14: =_xlfn.MAXIFS(Koreksi_Data!$C$7:$C$2719,Koreksi_Data!$B$7:$B$2719,$A14) -> 46235 | D14: =COUNTIFS(Koreksi_Data!$B$7:$B$2719,$A14,Koreksi_Data!$D$7:$D$2719,">=0") -> 152 | E14: =COUNTIFS(Koreksi_Data!$B$7:$B$2719,$A14,Koreksi_Data!$E$7:$E$2719,">=0") -> 89 | F14: =SUMPRODUCT((Koreksi_Data!$B$7:$B$2719=$A14)*ISNUMBER(Koreksi_Data!$E$7:$E$2719)*(Koreksi_Data!$D$7:$D$2719>0)) -> 64 | G14: =IFERROR(_xlfn.MINIFS(Koreksi_Data!$F$7:$F$2719,Koreksi_Data!$B$7:$B$2719,$A14,Koreksi_Data!$D$7:$D$2719,">=0"),"-") -> 0 | H14: =IFERROR(_xlfn.MAXIFS(Koreksi_Data!$F$7:$F$2719,Koreksi_Data!$B$7:$B$2719,$A14,Koreksi_Data!$D$7:$D$2719,">=0"),"-") -> 30.120482 | I14: =IFERROR(AVERAGEIFS(Koreksi_Data!$F$7:$F$2719,Koreksi_Data!$B$7:$B$2719,$A14,Koreksi_Data!$D$7:$D$2719,">=0"),"-") -> 1.4076752 | J14: =INDEX(Koreksi_Data!$F$7:$F$2719,MATCH($A14,Koreksi_Data!$B$7:$B$2719,0)+COUNTIF(Koreksi_Data!$B$7:$B$2719,$A14)-1) -> 1.2562814 | K14: =SUMPRODUCT((Koreksi_Data!$B$7:$B$2719=$A14)*Koreksi_Data!$D$7:$D$2719*Koreksi_Data!$T$7:$T$2719)/1000 -> 33.883126 | L14: =SUMPRODUCT((Koreksi_Data!$B$7:$B$2719=$A14)*Koreksi_Data!$G$7:$G$2719*Koreksi_Data!$T$7:$T$2719)/1000 -> 38.401572 | M14: =IF(K14=0,"-",L14/K14-1) -> 0.13335387 | N14: =IFERROR(SUMPRODUCT((Koreksi_Data!$B$7:$B$2719=$A14)*ISNUMBER(Koreksi_Data!$E$7:$E$2719)*Koreksi_Data!$D$7:$D$2719)/SUMPRODUCT((Koreksi_Data!$B$7:$B$2719=$A14)*ISNUMBER(Koreksi_Data!$D$7:$D$2719)*Koreksi_Data!$E$7:$E$2719),"-") -> 0.86183782
A15: KKNA-4 | B15: =_xlfn.MINIFS(Koreksi_Data!$C$7:$C$2719,Koreksi_Data!$B$7:$B$2719,$A15) -> 38353 | C15: =_xlfn.MAXIFS(Koreksi_Data!$C$7:$C$2719,Koreksi_Data!$B$7:$B$2719,$A15) -> 46235 | D15: =COUNTIFS(Koreksi_Data!$B$7:$B$2719,$A15,Koreksi_Data!$D$7:$D$2719,">=0") -> 244 | E15: =COUNTIFS(Koreksi_Data!$B$7:$B$2719,$A15,Koreksi_Data!$E$7:$E$2719,">=0") -> 102 | F15: =SUMPRODUCT((Koreksi_Data!$B$7:$B$2719=$A15)*ISNUMBER(Koreksi_Data!$E$7:$E$2719)*(Koreksi_Data!$D$7:$D$2719>0)) -> 32 | G15: =IFERROR(_xlfn.MINIFS(Koreksi_Data!$F$7:$F$2719,Koreksi_Data!$B$7:$B$2719,$A15,Koreksi_Data!$D$7:$D$2719,">=0"),"-") -> 0.49145299 | H15: =IFERROR(_xlfn.MAXIFS(Koreksi_Data!$F$7:$F$2719,Koreksi_Data!$B$7:$B$2719,$A15,Koreksi_Data!$D$7:$D$2719,">=0"),"-") -> 4.0083799 | I15: =IFERROR(AVERAGEIFS(Koreksi_Data!$F$7:$F$2719,Koreksi_Data!$B$7:$B$2719,$A15,Koreksi_Data!$D$7:$D$2719,">=0"),"-") -> 2.9127823 | J15: =INDEX(Koreksi_Data!$F$7:$F$2719,MATCH($A15,Koreksi_Data!$B$7:$B$2719,0)+COUNTIF(Koreksi_Data!$B$7:$B$2719,$A15)-1) -> 4.0083799 | K15: =SUMPRODUCT((Koreksi_Data!$B$7:$B$2719=$A15)*Koreksi_Data!$D$7:$D$2719*Koreksi_Data!$T$7:$T$2719)/1000 -> 260.8565 | L15: =SUMPRODUCT((Koreksi_Data!$B$7:$B$2719=$A15)*Koreksi_Data!$G$7:$G$2719*Koreksi_Data!$T$7:$T$2719)/1000 -> 469.54974 | M15: =IF(K15=0,"-",L15/K15-1) -> 0.80003081 | N15: =IFERROR(SUMPRODUCT((Koreksi_Data!$B$7:$B$2719=$A15)*ISNUMBER(Koreksi_Data!$E$7:$E$2719)*Koreksi_Data!$D$7:$D$2719)/SUMPRODUCT((Koreksi_Data!$B$7:$B$2719=$A15)*ISNUMBER(Koreksi_Data!$D$7:$D$2719)*Koreksi_Data!$E$7:$E$2719),"-") -> 0.67507342
A16: KKNA-5ST | B16: =_xlfn.MINIFS(Koreksi_Data!$C$7:$C$2719,Koreksi_Data!$B$7:$B$2719,$A16) -> 41153 | C16: =_xlfn.MAXIFS(Koreksi_Data!$C$7:$C$2719,Koreksi_Data!$B$7:$B$2719,$A16) -> 45748 | D16: =COUNTIFS(Koreksi_Data!$B$7:$B$2719,$A16,Koreksi_Data!$D$7:$D$2719,">=0") -> 152 | E16: =COUNTIFS(Koreksi_Data!$B$7:$B$2719,$A16,Koreksi_Data!$E$7:$E$2719,">=0") -> 70 | F16: =SUMPRODUCT((Koreksi_Data!$B$7:$B$2719=$A16)*ISNUMBER(Koreksi_Data!$E$7:$E$2719)*(Koreksi_Data!$D$7:$D$2719>0)) -> 54 | G16: =IFERROR(_xlfn.MINIFS(Koreksi_Data!$F$7:$F$2719,Koreksi_Data!$B$7:$B$2719,$A16,Koreksi_Data!$D$7:$D$2719,">=0"),"-") -> 0 | H16: =IFERROR(_xlfn.MAXIFS(Koreksi_Data!$F$7:$F$2719,Koreksi_Data!$B$7:$B$2719,$A16,Koreksi_Data!$D$7:$D$2719,">=0"),"-") -> 3.8380282 | I16: =IFERROR(AVERAGEIFS(Koreksi_Data!$F$7:$F$2719,Koreksi_Data!$B$7:$B$2719,$A16,Koreksi_Data!$D$7:$D$2719,">=0"),"-") -> 1.0876729 | J16: =INDEX(Koreksi_Data!$F$7:$F$2719,MATCH($A16,Koreksi_Data!$B$7:$B$2719,0)+COUNTIF(Koreksi_Data!$B$7:$B$2719,$A16)-1) -> 1 | K16: =SUMPRODUCT((Koreksi_Data!$B$7:$B$2719=$A16)*Koreksi_Data!$D$7:$D$2719*Koreksi_Data!$T$7:$T$2719)/1000 -> 111.87881 | L16: =SUMPRODUCT((Koreksi_Data!$B$7:$B$2719=$A16)*Koreksi_Data!$G$7:$G$2719*Koreksi_Data!$T$7:$T$2719)/1000 -> 99.872267 | M16: =IF(K16=0,"-",L16/K16-1) -> -0.10731741 | N16: =IFERROR(SUMPRODUCT((Koreksi_Data!$B$7:$B$2719=$A16)*ISNUMBER(Koreksi_Data!$E$7:$E$2719)*Koreksi_Data!$D$7:$D$2719)/SUMPRODUCT((Koreksi_Data!$B$7:$B$2719=$A16)*ISNUMBER(Koreksi_Data!$D$7:$D$2719)*Koreksi_Data!$E$7:$E$2719),"-") -> 1.1179674
A17: KKNB-1 | B17: =_xlfn.MINIFS(Koreksi_Data!$C$7:$C$2719,Koreksi_Data!$B$7:$B$2719,$A17) -> 42461 | C17: =_xlfn.MAXIFS(Koreksi_Data!$C$7:$C$2719,Koreksi_Data!$B$7:$B$2719,$A17) -> 46235 | D17: =COUNTIFS(Koreksi_Data!$B$7:$B$2719,$A17,Koreksi_Data!$D$7:$D$2719,">=0") -> 104 | E17: =COUNTIFS(Koreksi_Data!$B$7:$B$2719,$A17,Koreksi_Data!$E$7:$E$2719,">=0") -> 39 | F17: =SUMPRODUCT((Koreksi_Data!$B$7:$B$2719=$A17)*ISNUMBER(Koreksi_Data!$E$7:$E$2719)*(Koreksi_Data!$D$7:$D$2719>0)) -> 0 | G17: =IFERROR(_xlfn.MINIFS(Koreksi_Data!$F$7:$F$2719,Koreksi_Data!$B$7:$B$2719,$A17,Koreksi_Data!$D$7:$D$2719,">=0"),"-") -> 1 | H17: =IFERROR(_xlfn.MAXIFS(Koreksi_Data!$F$7:$F$2719,Koreksi_Data!$B$7:$B$2719,$A17,Koreksi_Data!$D$7:$D$2719,">=0"),"-") -> 1 | I17: =IFERROR(AVERAGEIFS(Koreksi_Data!$F$7:$F$2719,Koreksi_Data!$B$7:$B$2719,$A17,Koreksi_Data!$D$7:$D$2719,">=0"),"-") -> 1 | J17: =INDEX(Koreksi_Data!$F$7:$F$2719,MATCH($A17,Koreksi_Data!$B$7:$B$2719,0)+COUNTIF(Koreksi_Data!$B$7:$B$2719,$A17)-1) -> 1 | K17: =SUMPRODUCT((Koreksi_Data!$B$7:$B$2719=$A17)*Koreksi_Data!$D$7:$D$2719*Koreksi_Data!$T$7:$T$2719)/1000 -> 0 | L17: =SUMPRODUCT((Koreksi_Data!$B$7:$B$2719=$A17)*Koreksi_Data!$G$7:$G$2719*Koreksi_Data!$T$7:$T$2719)/1000 -> 0 | M17: =IF(K17=0,"-",L17/K17-1) -> - | N17: =IFERROR(SUMPRODUCT((Koreksi_Data!$B$7:$B$2719=$A17)*ISNUMBER(Koreksi_Data!$E$7:$E$2719)*Koreksi_Data!$D$7:$D$2719)/SUMPRODUCT((Koreksi_Data!$B$7:$B$2719=$A17)*ISNUMBER(Koreksi_Data!$D$7:$D$2719)*Koreksi_Data!$E$7:$E$2719),"-") -> -
... A20: KKNB-2 | B20: =_xlfn.MINIFS(Koreksi_Data!$C$7:$C$2719,Koreksi_Data!$B$7:$B$2719,$A20) -> 36281 | C20: =_xlfn.MAXIFS(Koreksi_Data!$C$7:$C$2719,Koreksi_Data!$B$7:$B$2719,$A20) -> 45748 | D20: =COUNTIFS(Koreksi_Data!$B$7:$B$2719,$A20,Koreksi_Data!$D$7:$D$2719,">=0") -> 279 | E20: =COUNTIFS(Koreksi_Data!$B$7:$B$2719,$A20,Koreksi_Data!$E$7:$E$2719,">=0") -> 55 | F20: =SUMPRODUCT((Koreksi_Data!$B$7:$B$2719=$A20)*ISNUMBER(Koreksi_Data!$E$7:$E$2719)*(Koreksi_Data!$D$7:$D$2719>0)) -> 37 | G20: =IFERROR(_xlfn.MINIFS(Koreksi_Data!$F$7:$F$2719,Koreksi_Data!$B$7:$B$2719,$A20,Koreksi_Data!$D$7:$D$2719,">=0"),"-") -> 0 | H20: =IFERROR(_xlfn.MAXIFS(Koreksi_Data!$F$7:$F$2719,Koreksi_Data!$B$7:$B$2719,$A20,Koreksi_Data!$D$7:$D$2719,">=0"),"-") -> 2.4351145 | I20: =IFERROR(AVERAGEIFS(Koreksi_Data!$F$7:$F$2719,Koreksi_Data!$B$7:$B$2719,$A20,Koreksi_Data!$D$7:$D$2719,">=0"),"-") -> 1.3575873 | J20: =INDEX(Koreksi_Data!$F$7:$F$2719,MATCH($A20,Koreksi_Data!$B$7:$B$2719,0)+COUNTIF(Koreksi_Data!$B$7:$B$2719,$A20)-1) -> 1 | K20: =SUMPRODUCT((Koreksi_Data!$B$7:$B$2719=$A20)*Koreksi_Data!$D$7:$D$2719*Koreksi_Data!$T$7:$T$2719)/1000 -> 894.75838 | L20: =SUMPRODUCT((Koreksi_Data!$B$7:$B$2719=$A20)*Koreksi_Data!$G$7:$G$2719*Koreksi_Data!$T$7:$T$2719)/1000 -> 1130.505 | M20: =IF(K20=0,"-",L20/K20-1) -> 0.26347519 | N20: =IFERROR(SUMPRODUCT((Koreksi_Data!$B$7:$B$2719=$A20)*ISNUMBER(Koreksi_Data!$E$7:$E$2719)*Koreksi_Data!$D$7:$D$2719)/SUMPRODUCT((Koreksi_Data!$B$7:$B$2719=$A20)*ISNUMBER(Koreksi_Data!$D$7:$D$2719)*Koreksi_Data!$E$7:$E$2719),"-") -> 0.88460968
A21: TOTAL LAPANGAN | K21: =SUM(K6:K20) -> 5910.6768 | L21: =SUM(L6:L20) -> 8007.2857 | M21: =IF(K21=0,"-",L21/K21-1) -> 0.35471553
A24: GAS (MCFPD) | kumulatif dalam MMscf
A25: Sumur | B25: Awal data | C25: Akhir data | D25: Bulan Prod | E25: Bulan WT | F25: Titik koreksi | G25: Multiplier min | H25: Multiplier maks | I25: Multiplier rata-rata | J25: Multiplier terakhir | K25: Kum. Sebelum | L25: Kum. Sesudah | M25: Selisih (%) | N25: Prod/WT sebelum (bulan WT)
A26: KKA-1 | B26: =_xlfn.MINIFS(Koreksi_Data!$C$7:$C$2719,Koreksi_Data!$B$7:$B$2719,$A26) -> 37438 | C26: =_xlfn.MAXIFS(Koreksi_Data!$C$7:$C$2719,Koreksi_Data!$B$7:$B$2719,$A26) -> 46266 | D26: =COUNTIFS(Koreksi_Data!$B$7:$B$2719,$A26,Koreksi_Data!$H$7:$H$2719,">=0") -> 272 | E26: =COUNTIFS(Koreksi_Data!$B$7:$B$2719,$A26,Koreksi_Data!$I$7:$I$2719,">=0") -> 152 | F26: =SUMPRODUCT((Koreksi_Data!$B$7:$B$2719=$A26)*ISNUMBER(Koreksi_Data!$I$7:$I$2719)*(Koreksi_Data!$H$7:$H$2719>0)) -> 117 | G26: =IFERROR(_xlfn.MINIFS(Koreksi_Data!$J$7:$J$2719,Koreksi_Data!$B$7:$B$2719,$A26,Koreksi_Data!$H$7:$H$2719,">=0"),"-") -> 0 | H26: =IFERROR(_xlfn.MAXIFS(Koreksi_Data!$J$7:$J$2719,Koreksi_Data!$B$7:$B$2719,$A26,Koreksi_Data!$H$7:$H$2719,">=0"),"-") -> 16.506224 | I26: =IFERROR(AVERAGEIFS(Koreksi_Data!$J$7:$J$2719,Koreksi_Data!$B$7:$B$2719,$A26,Koreksi_Data!$H$7:$H$2719,">=0"),"-") -> 1.7620945 | J26: =INDEX(Koreksi_Data!$J$7:$J$2719,MATCH($A26,Koreksi_Data!$B$7:$B$2719,0)+COUNTIF(Koreksi_Data!$B$7:$B$2719,$A26)-1) -> 1 | K26: =SUMPRODUCT((Koreksi_Data!$B$7:$B$2719=$A26)*Koreksi_Data!$H$7:$H$2719*Koreksi_Data!$T$7:$T$2719)/1000 -> 15520.589 | L26: =SUMPRODUCT((Koreksi_Data!$B$7:$B$2719=$A26)*Koreksi_Data!$K$7:$K$2719*Koreksi_Data!$T$7:$T$2719)/1000 -> 19284.1 | M26: =IF(K26=0,"-",L26/K26-1) -> 0.24248503 | N26: =IFERROR(SUMPRODUCT((Koreksi_Data!$B$7:$B$2719=$A26)*ISNUMBER(Koreksi_Data!$I$7:$I$2719)*Koreksi_Data!$H$7:$H$2719)/SUMPRODUCT((Koreksi_Data!$B$7:$B$2719=$A26)*ISNUMBER(Koreksi_Data!$H$7:$H$2719)*Koreksi_Data!$I$7:$I$2719),"-") -> 0.6493701
A27: KKA-2ST2L | B27: =_xlfn.MINIFS(Koreksi_Data!$C$7:$C$2719,Koreksi_Data!$B$7:$B$2719,$A27) -> 39814 | C27: =_xlfn.MAXIFS(Koreksi_Data!$C$7:$C$2719,Koreksi_Data!$B$7:$B$2719,$A27) -> 42856 | D27: =COUNTIFS(Koreksi_Data!$B$7:$B$2719,$A27,Koreksi_Data!$H$7:$H$2719,">=0") -> 90 | E27: =COUNTIFS(Koreksi_Data!$B$7:$B$2719,$A27,Koreksi_Data!$I$7:$I$2719,">=0") -> 22 | F27: =SUMPRODUCT((Koreksi_Data!$B$7:$B$2719=$A27)*ISNUMBER(Koreksi_Data!$I$7:$I$2719)*(Koreksi_Data!$H$7:$H$2719>0)) -> 8 | G27: =IFERROR(_xlfn.MINIFS(Koreksi_Data!$J$7:$J$2719,Koreksi_Data!$B$7:$B$2719,$A27,Koreksi_Data!$H$7:$H$2719,">=0"),"-") -> 0.8478582 | H27: =IFERROR(_xlfn.MAXIFS(Koreksi_Data!$J$7:$J$2719,Koreksi_Data!$B$7:$B$2719,$A27,Koreksi_Data!$H$7:$H$2719,">=0"),"-") -> 33.256785 | I27: =IFERROR(AVERAGEIFS(Koreksi_Data!$J$7:$J$2719,Koreksi_Data!$B$7:$B$2719,$A27,Koreksi_Data!$H$7:$H$2719,">=0"),"-") -> 10.501915 | J27: =INDEX(Koreksi_Data!$J$7:$J$2719,MATCH($A27,Koreksi_Data!$B$7:$B$2719,0)+COUNTIF(Koreksi_Data!$B$7:$B$2719,$A27)-1) -> 0.8478582 | K27: =SUMPRODUCT((Koreksi_Data!$B$7:$B$2719=$A27)*Koreksi_Data!$H$7:$H$2719*Koreksi_Data!$T$7:$T$2719)/1000 -> 1823.146 | L27: =SUMPRODUCT((Koreksi_Data!$B$7:$B$2719=$A27)*Koreksi_Data!$K$7:$K$2719*Koreksi_Data!$T$7:$T$2719)/1000 -> 16581.88 | M27: =IF(K27=0,"-",L27/K27-1) -> 8.0952012 | N27: =IFERROR(SUMPRODUCT((Koreksi_Data!$B$7:$B$2719=$A27)*ISNUMBER(Koreksi_Data!$I$7:$I$2719)*Koreksi_Data!$H$7:$H$2719)/SUMPRODUCT((Koreksi_Data!$B$7:$B$2719=$A27)*ISNUMBER(Koreksi_Data!$H$7:$H$2719)*Koreksi_Data!$I$7:$I$2719),"-") -> 0.22889552
A28: KKA-3 | B28: =_xlfn.MINIFS(Koreksi_Data!$C$7:$C$2719,Koreksi_Data!$B$7:$B$2719,$A28) -> 39845 | C28: =_xlfn.MAXIFS(Koreksi_Data!$C$7:$C$2719,Koreksi_Data!$B$7:$B$2719,$A28) -> 46266 | D28: =COUNTIFS(Koreksi_Data!$B$7:$B$2719,$A28,Koreksi_Data!$H$7:$H$2719,">=0") -> 193 | E28: =COUNTIFS(Koreksi_Data!$B$7:$B$2719,$A28,Koreksi_Data!$I$7:$I$2719,">=0") -> 78 | F28: =SUMPRODUCT((Koreksi_Data!$B$7:$B$2719=$A28)*ISNUMBER(Koreksi_Data!$I$7:$I$2719)*(Koreksi_Data!$H$7:$H$2719>0)) -> 52 | G28: =IFERROR(_xlfn.MINIFS(Koreksi_Data!$J$7:$J$2719,Koreksi_Data!$B$7:$B$2719,$A28,Koreksi_Data!$H$7:$H$2719,">=0"),"-") -> 0 | H28: =IFERROR(_xlfn.MAXIFS(Koreksi_Data!$J$7:$J$2719,Koreksi_Data!$B$7:$B$2719,$A28,Koreksi_Data!$H$7:$H$2719,">=0"),"-") -> 31.389549 | I28: =IFERROR(AVERAGEIFS(Koreksi_Data!$J$7:$J$2719,Koreksi_Data!$B$7:$B$2719,$A28,Koreksi_Data!$H$7:$H$2719,">=0"),"-") -> 3.411565 | J28: =INDEX(Koreksi_Data!$J$7:$J$2719,MATCH($A28,Koreksi_Data!$B$7:$B$2719,0)+COUNTIF(Koreksi_Data!$B$7:$B$2719,$A28)-1) -> 2.6511628 | K28: =SUMPRODUCT((Koreksi_Data!$B$7:$B$2719=$A28)*Koreksi_Data!$H$7:$H$2719*Koreksi_Data!$T$7:$T$2719)/1000 -> 3793.6932 | L28: =SUMPRODUCT((Koreksi_Data!$B$7:$B$2719=$A28)*Koreksi_Data!$K$7:$K$2719*Koreksi_Data!$T$7:$T$2719)/1000 -> 7090.3859 | M28: =IF(K28=0,"-",L28/K28-1) -> 0.86899296 | N28: =IFERROR(SUMPRODUCT((Koreksi_Data!$B$7:$B$2719=$A28)*ISNUMBER(Koreksi_Data!$I$7:$I$2719)*Koreksi_Data!$H$7:$H$2719)/SUMPRODUCT((Koreksi_Data!$B$7:$B$2719=$A28)*ISNUMBER(Koreksi_Data!$H$7:$H$2719)*Koreksi_Data!$I$7:$I$2719),"-") -> 0.39881875
A29: KKA-4 | B29: =_xlfn.MINIFS(Koreksi_Data!$C$7:$C$2719,Koreksi_Data!$B$7:$B$2719,$A29) -> 40210 | C29: =_xlfn.MAXIFS(Koreksi_Data!$C$7:$C$2719,Koreksi_Data!$B$7:$B$2719,$A29) -> 46113 | D29: =COUNTIFS(Koreksi_Data!$B$7:$B$2719,$A29,Koreksi_Data!$H$7:$H$2719,">=0") -> 172 | E29: =COUNTIFS(Koreksi_Data!$B$7:$B$2719,$A29,Koreksi_Data!$I$7:$I$2719,">=0") -> 92 | F29: =SUMPRODUCT((Koreksi_Data!$B$7:$B$2719=$A29)*ISNUMBER(Koreksi_Data!$I$7:$I$2719)*(Koreksi_Data!$H$7:$H$2719>0)) -> 68 | G29: =IFERROR(_xlfn.MINIFS(Koreksi_Data!$J$7:$J$2719,Koreksi_Data!$B$7:$B$2719,$A29,Koreksi_Data!$H$7:$H$2719,">=0"),"-") -> 0.64076859 | H29: =IFERROR(_xlfn.MAXIFS(Koreksi_Data!$J$7:$J$2719,Koreksi_Data!$B$7:$B$2719,$A29,Koreksi_Data!$H$7:$H$2719,">=0"),"-") -> 15.472393 | I29: =IFERROR(AVERAGEIFS(Koreksi_Data!$J$7:$J$2719,Koreksi_Data!$B$7:$B$2719,$A29,Koreksi_Data!$H$7:$H$2719,">=0"),"-") -> 2.6306278 | J29: =INDEX(Koreksi_Data!$J$7:$J$2719,MATCH($A29,Koreksi_Data!$B$7:$B$2719,0)+COUNTIF(Koreksi_Data!$B$7:$B$2719,$A29)-1) -> 1.0447427 | K29: =SUMPRODUCT((Koreksi_Data!$B$7:$B$2719=$A29)*Koreksi_Data!$H$7:$H$2719*Koreksi_Data!$T$7:$T$2719)/1000 -> 3916.789 | L29: =SUMPRODUCT((Koreksi_Data!$B$7:$B$2719=$A29)*Koreksi_Data!$K$7:$K$2719*Koreksi_Data!$T$7:$T$2719)/1000 -> 9650.2676 | M29: =IF(K29=0,"-",L29/K29-1) -> 1.4638212 | N29: =IFERROR(SUMPRODUCT((Koreksi_Data!$B$7:$B$2719=$A29)*ISNUMBER(Koreksi_Data!$I$7:$I$2719)*Koreksi_Data!$H$7:$H$2719)/SUMPRODUCT((Koreksi_Data!$B$7:$B$2719=$A29)*ISNUMBER(Koreksi_Data!$H$7:$H$2719)*Koreksi_Data!$I$7:$I$2719),"-") -> 0.33368465
A30: KKNA-1L | B30: =_xlfn.MINIFS(Koreksi_Data!$C$7:$C$2719,Koreksi_Data!$B$7:$B$2719,$A30) -> 36161 | C30: =_xlfn.MAXIFS(Koreksi_Data!$C$7:$C$2719,Koreksi_Data!$B$7:$B$2719,$A30) -> 42430 | D30: =COUNTIFS(Koreksi_Data!$B$7:$B$2719,$A30,Koreksi_Data!$H$7:$H$2719,">=0") -> 151 | E30: =COUNTIFS(Koreksi_Data!$B$7:$B$2719,$A30,Koreksi_Data!$I$7:$I$2719,">=0") -> 59 | F30: =SUMPRODUCT((Koreksi_Data!$B$7:$B$2719=$A30)*ISNUMBER(Koreksi_Data!$I$7:$I$2719)*(Koreksi_Data!$H$7:$H$2719>0)) -> 59 | G30: =IFERROR(_xlfn.MINIFS(Koreksi_Data!$J$7:$J$2719,Koreksi_Data!$B$7:$B$2719,$A30,Koreksi_Data!$H$7:$H$2719,">=0"),"-") -> 0 | H30: =IFERROR(_xlfn.MAXIFS(Koreksi_Data!$J$7:$J$2719,Koreksi_Data!$B$7:$B$2719,$A30,Koreksi_Data!$H$7:$H$2719,">=0"),"-") -> 6.0933713 | I30: =IFERROR(AVERAGEIFS(Koreksi_Data!$J$7:$J$2719,Koreksi_Data!$B$7:$B$2719,$A30,Koreksi_Data!$H$7:$H$2719,">=0"),"-") -> 2.4321359 | J30: =INDEX(Koreksi_Data!$J$7:$J$2719,MATCH($A30,Koreksi_Data!$B$7:$B$2719,0)+COUNTIF(Koreksi_Data!$B$7:$B$2719,$A30)-1) -> 0 | K30: =SUMPRODUCT((Koreksi_Data!$B$7:$B$2719=$A30)*Koreksi_Data!$H$7:$H$2719*Koreksi_Data!$T$7:$T$2719)/1000 -> 7525.571 | L30: =SUMPRODUCT((Koreksi_Data!$B$7:$B$2719=$A30)*Koreksi_Data!$K$7:$K$2719*Koreksi_Data!$T$7:$T$2719)/1000 -> 16605.424 | M30: =IF(K30=0,"-",L30/K30-1) -> 1.2065334 | N30: =IFERROR(SUMPRODUCT((Koreksi_Data!$B$7:$B$2719=$A30)*ISNUMBER(Koreksi_Data!$I$7:$I$2719)*Koreksi_Data!$H$7:$H$2719)/SUMPRODUCT((Koreksi_Data!$B$7:$B$2719=$A30)*ISNUMBER(Koreksi_Data!$H$7:$H$2719)*Koreksi_Data!$I$7:$I$2719),"-") -> 0.43700201
A31: KKNA-1S | B31: =_xlfn.MINIFS(Koreksi_Data!$C$7:$C$2719,Koreksi_Data!$B$7:$B$2719,$A31) -> 36495 | C31: =_xlfn.MAXIFS(Koreksi_Data!$C$7:$C$2719,Koreksi_Data!$B$7:$B$2719,$A31) -> 42430 | D31: =COUNTIFS(Koreksi_Data!$B$7:$B$2719,$A31,Koreksi_Data!$H$7:$H$2719,">=0") -> 139 | E31: =COUNTIFS(Koreksi_Data!$B$7:$B$2719,$A31,Koreksi_Data!$I$7:$I$2719,">=0") -> 56 | F31: =SUMPRODUCT((Koreksi_Data!$B$7:$B$2719=$A31)*ISNUMBER(Koreksi_Data!$I$7:$I$2719)*(Koreksi_Data!$H$7:$H$2719>0)) -> 56 | G31: =IFERROR(_xlfn.MINIFS(Koreksi_Data!$J$7:$J$2719,Koreksi_Data!$B$7:$B$2719,$A31,Koreksi_Data!$H$7:$H$2719,">=0"),"-") -> 0.2009072 | H31: =IFERROR(_xlfn.MAXIFS(Koreksi_Data!$J$7:$J$2719,Koreksi_Data!$B$7:$B$2719,$A31,Koreksi_Data!$H$7:$H$2719,">=0"),"-") -> 49.363636 | I31: =IFERROR(AVERAGEIFS(Koreksi_Data!$J$7:$J$2719,Koreksi_Data!$B$7:$B$2719,$A31,Koreksi_Data!$H$7:$H$2719,">=0"),"-") -> 2.4183233 | J31: =INDEX(Koreksi_Data!$J$7:$J$2719,MATCH($A31,Koreksi_Data!$B$7:$B$2719,0)+COUNTIF(Koreksi_Data!$B$7:$B$2719,$A31)-1) -> 0.76881464 | K31: =SUMPRODUCT((Koreksi_Data!$B$7:$B$2719=$A31)*Koreksi_Data!$H$7:$H$2719*Koreksi_Data!$T$7:$T$2719)/1000 -> 9949.6532 | L31: =SUMPRODUCT((Koreksi_Data!$B$7:$B$2719=$A31)*Koreksi_Data!$K$7:$K$2719*Koreksi_Data!$T$7:$T$2719)/1000 -> 13103.962 | M31: =IF(K31=0,"-",L31/K31-1) -> 0.31702702 | N31: =IFERROR(SUMPRODUCT((Koreksi_Data!$B$7:$B$2719=$A31)*ISNUMBER(Koreksi_Data!$I$7:$I$2719)*Koreksi_Data!$H$7:$H$2719)/SUMPRODUCT((Koreksi_Data!$B$7:$B$2719=$A31)*ISNUMBER(Koreksi_Data!$H$7:$H$2719)*Koreksi_Data!$I$7:$I$2719),"-") -> 0.74890949
A32: KKNA-2 | B32: =_xlfn.MINIFS(Koreksi_Data!$C$7:$C$2719,Koreksi_Data!$B$7:$B$2719,$A32) -> 36161 | C32: =_xlfn.MAXIFS(Koreksi_Data!$C$7:$C$2719,Koreksi_Data!$B$7:$B$2719,$A32) -> 45505 | D32: =COUNTIFS(Koreksi_Data!$B$7:$B$2719,$A32,Koreksi_Data!$H$7:$H$2719,">=0") -> 153 | E32: =COUNTIFS(Koreksi_Data!$B$7:$B$2719,$A32,Koreksi_Data!$I$7:$I$2719,">=0") -> 54 | F32: =SUMPRODUCT((Koreksi_Data!$B$7:$B$2719=$A32)*ISNUMBER(Koreksi_Data!$I$7:$I$2719)*(Koreksi_Data!$H$7:$H$2719>0)) -> 49 | G32: =IFERROR(_xlfn.MINIFS(Koreksi_Data!$J$7:$J$2719,Koreksi_Data!$B$7:$B$2719,$A32,Koreksi_Data!$H$7:$H$2719,">=0"),"-") -> 0 | H32: =IFERROR(_xlfn.MAXIFS(Koreksi_Data!$J$7:$J$2719,Koreksi_Data!$B$7:$B$2719,$A32,Koreksi_Data!$H$7:$H$2719,">=0"),"-") -> 6.0931677 | I32: =IFERROR(AVERAGEIFS(Koreksi_Data!$J$7:$J$2719,Koreksi_Data!$B$7:$B$2719,$A32,Koreksi_Data!$H$7:$H$2719,">=0"),"-") -> 2.2316683 | J32: =INDEX(Koreksi_Data!$J$7:$J$2719,MATCH($A32,Koreksi_Data!$B$7:$B$2719,0)+COUNTIF(Koreksi_Data!$B$7:$B$2719,$A32)-1) -> 1.5846679 | K32: =SUMPRODUCT((Koreksi_Data!$B$7:$B$2719=$A32)*Koreksi_Data!$H$7:$H$2719*Koreksi_Data!$T$7:$T$2719)/1000 -> 4722.249 | L32: =SUMPRODUCT((Koreksi_Data!$B$7:$B$2719=$A32)*Koreksi_Data!$K$7:$K$2719*Koreksi_Data!$T$7:$T$2719)/1000 -> 11400.825 | M32: =IF(K32=0,"-",L32/K32-1) -> 1.4142786 | N32: =IFERROR(SUMPRODUCT((Koreksi_Data!$B$7:$B$2719=$A32)*ISNUMBER(Koreksi_Data!$I$7:$I$2719)*Koreksi_Data!$H$7:$H$2719)/SUMPRODUCT((Koreksi_Data!$B$7:$B$2719=$A32)*ISNUMBER(Koreksi_Data!$H$7:$H$2719)*Koreksi_Data!$I$7:$I$2719),"-") -> 0.45414571
A33: KKNA-3 | B33: =_xlfn.MINIFS(Koreksi_Data!$C$7:$C$2719,Koreksi_Data!$B$7:$B$2719,$A33) -> 37622 | C33: =_xlfn.MAXIFS(Koreksi_Data!$C$7:$C$2719,Koreksi_Data!$B$7:$B$2719,$A33) -> 42552 | D33: =COUNTIFS(Koreksi_Data!$B$7:$B$2719,$A33,Koreksi_Data!$H$7:$H$2719,">=0") -> 131 | E33: =COUNTIFS(Koreksi_Data!$B$7:$B$2719,$A33,Koreksi_Data!$I$7:$I$2719,">=0") -> 62 | F33: =SUMPRODUCT((Koreksi_Data!$B$7:$B$2719=$A33)*ISNUMBER(Koreksi_Data!$I$7:$I$2719)*(Koreksi_Data!$H$7:$H$2719>0)) -> 48 | G33: =IFERROR(_xlfn.MINIFS(Koreksi_Data!$J$7:$J$2719,Koreksi_Data!$B$7:$B$2719,$A33,Koreksi_Data!$H$7:$H$2719,">=0"),"-") -> 0.55561808 | H33: =IFERROR(_xlfn.MAXIFS(Koreksi_Data!$J$7:$J$2719,Koreksi_Data!$B$7:$B$2719,$A33,Koreksi_Data!$H$7:$H$2719,">=0"),"-") -> 3.0465612 | I33: =IFERROR(AVERAGEIFS(Koreksi_Data!$J$7:$J$2719,Koreksi_Data!$B$7:$B$2719,$A33,Koreksi_Data!$H$7:$H$2719,">=0"),"-") -> 1.4981634 | J33: =INDEX(Koreksi_Data!$J$7:$J$2719,MATCH($A33,Koreksi_Data!$B$7:$B$2719,0)+COUNTIF(Koreksi_Data!$B$7:$B$2719,$A33)-1) -> 1.869863 | K33: =SUMPRODUCT((Koreksi_Data!$B$7:$B$2719=$A33)*Koreksi_Data!$H$7:$H$2719*Koreksi_Data!$T$7:$T$2719)/1000 -> 12751.505 | L33: =SUMPRODUCT((Koreksi_Data!$B$7:$B$2719=$A33)*Koreksi_Data!$K$7:$K$2719*Koreksi_Data!$T$7:$T$2719)/1000 -> 15218.285 | M33: =IF(K33=0,"-",L33/K33-1) -> 0.19345008 | N33: =IFERROR(SUMPRODUCT((Koreksi_Data!$B$7:$B$2719=$A33)*ISNUMBER(Koreksi_Data!$I$7:$I$2719)*Koreksi_Data!$H$7:$H$2719)/SUMPRODUCT((Koreksi_Data!$B$7:$B$2719=$A33)*ISNUMBER(Koreksi_Data!$H$7:$H$2719)*Koreksi_Data!$I$7:$I$2719),"-") -> 0.65669987
A34: KKNA-3ST | B34: =_xlfn.MINIFS(Koreksi_Data!$C$7:$C$2719,Koreksi_Data!$B$7:$B$2719,$A34) -> 41153 | C34: =_xlfn.MAXIFS(Koreksi_Data!$C$7:$C$2719,Koreksi_Data!$B$7:$B$2719,$A34) -> 46235 | D34: =COUNTIFS(Koreksi_Data!$B$7:$B$2719,$A34,Koreksi_Data!$H$7:$H$2719,">=0") -> 152 | E34: =COUNTIFS(Koreksi_Data!$B$7:$B$2719,$A34,Koreksi_Data!$I$7:$I$2719,">=0") -> 89 | F34: =SUMPRODUCT((Koreksi_Data!$B$7:$B$2719=$A34)*ISNUMBER(Koreksi_Data!$I$7:$I$2719)*(Koreksi_Data!$H$7:$H$2719>0)) -> 78 | G34: =IFERROR(_xlfn.MINIFS(Koreksi_Data!$J$7:$J$2719,Koreksi_Data!$B$7:$B$2719,$A34,Koreksi_Data!$H$7:$H$2719,">=0"),"-") -> 0 | H34: =IFERROR(_xlfn.MAXIFS(Koreksi_Data!$J$7:$J$2719,Koreksi_Data!$B$7:$B$2719,$A34,Koreksi_Data!$H$7:$H$2719,">=0"),"-") -> 24.419192 | I34: =IFERROR(AVERAGEIFS(Koreksi_Data!$J$7:$J$2719,Koreksi_Data!$B$7:$B$2719,$A34,Koreksi_Data!$H$7:$H$2719,">=0"),"-") -> 2.1650793 | J34: =INDEX(Koreksi_Data!$J$7:$J$2719,MATCH($A34,Koreksi_Data!$B$7:$B$2719,0)+COUNTIF(Koreksi_Data!$B$7:$B$2719,$A34)-1) -> 1.103404 | K34: =SUMPRODUCT((Koreksi_Data!$B$7:$B$2719=$A34)*Koreksi_Data!$H$7:$H$2719*Koreksi_Data!$T$7:$T$2719)/1000 -> 6729.827 | L34: =SUMPRODUCT((Koreksi_Data!$B$7:$B$2719=$A34)*Koreksi_Data!$K$7:$K$2719*Koreksi_Data!$T$7:$T$2719)/1000 -> 10189.507 | M34: =IF(K34=0,"-",L34/K34-1) -> 0.51408159 | N34: =IFERROR(SUMPRODUCT((Koreksi_Data!$B$7:$B$2719=$A34)*ISNUMBER(Koreksi_Data!$I$7:$I$2719)*Koreksi_Data!$H$7:$H$2719)/SUMPRODUCT((Koreksi_Data!$B$7:$B$2719=$A34)*ISNUMBER(Koreksi_Data!$H$7:$H$2719)*Koreksi_Data!$I$7:$I$2719),"-") -> 0.75558264
A35: KKNA-4 | B35: =_xlfn.MINIFS(Koreksi_Data!$C$7:$C$2719,Koreksi_Data!$B$7:$B$2719,$A35) -> 38353 | C35: =_xlfn.MAXIFS(Koreksi_Data!$C$7:$C$2719,Koreksi_Data!$B$7:$B$2719,$A35) -> 46235 | D35: =COUNTIFS(Koreksi_Data!$B$7:$B$2719,$A35,Koreksi_Data!$H$7:$H$2719,">=0") -> 244 | E35: =COUNTIFS(Koreksi_Data!$B$7:$B$2719,$A35,Koreksi_Data!$I$7:$I$2719,">=0") -> 102 | F35: =SUMPRODUCT((Koreksi_Data!$B$7:$B$2719=$A35)*ISNUMBER(Koreksi_Data!$I$7:$I$2719)*(Koreksi_Data!$H$7:$H$2719>0)) -> 74 | G35: =IFERROR(_xlfn.MINIFS(Koreksi_Data!$J$7:$J$2719,Koreksi_Data!$B$7:$B$2719,$A35,Koreksi_Data!$H$7:$H$2719,">=0"),"-") -> 0 | H35: =IFERROR(_xlfn.MAXIFS(Koreksi_Data!$J$7:$J$2719,Koreksi_Data!$B$7:$B$2719,$A35,Koreksi_Data!$H$7:$H$2719,">=0"),"-") -> 2.4202112 | I35: =IFERROR(AVERAGEIFS(Koreksi_Data!$J$7:$J$2719,Koreksi_Data!$B$7:$B$2719,$A35,Koreksi_Data!$H$7:$H$2719,">=0"),"-") -> 1.4111633 | J35: =INDEX(Koreksi_Data!$J$7:$J$2719,MATCH($A35,Koreksi_Data!$B$7:$B$2719,0)+COUNTIF(Koreksi_Data!$B$7:$B$2719,$A35)-1) -> 1.0303797 | K35: =SUMPRODUCT((Koreksi_Data!$B$7:$B$2719=$A35)*Koreksi_Data!$H$7:$H$2719*Koreksi_Data!$T$7:$T$2719)/1000 -> 13894.936 | L35: =SUMPRODUCT((Koreksi_Data!$B$7:$B$2719=$A35)*Koreksi_Data!$K$7:$K$2719*Koreksi_Data!$T$7:$T$2719)/1000 -> 16699.966 | M35: =IF(K35=0,"-",L35/K35-1) -> 0.20187427 | N35: =IFERROR(SUMPRODUCT((Koreksi_Data!$B$7:$B$2719=$A35)*ISNUMBER(Koreksi_Data!$I$7:$I$2719)*Koreksi_Data!$H$7:$H$2719)/SUMPRODUCT((Koreksi_Data!$B$7:$B$2719=$A35)*ISNUMBER(Koreksi_Data!$H$7:$H$2719)*Koreksi_Data!$I$7:$I$2719),"-") -> 0.65011068
A36: KKNA-5ST | B36: =_xlfn.MINIFS(Koreksi_Data!$C$7:$C$2719,Koreksi_Data!$B$7:$B$2719,$A36) -> 41153 | C36: =_xlfn.MAXIFS(Koreksi_Data!$C$7:$C$2719,Koreksi_Data!$B$7:$B$2719,$A36) -> 45748 | D36: =COUNTIFS(Koreksi_Data!$B$7:$B$2719,$A36,Koreksi_Data!$H$7:$H$2719,">=0") -> 152 | E36: =COUNTIFS(Koreksi_Data!$B$7:$B$2719,$A36,Koreksi_Data!$I$7:$I$2719,">=0") -> 70 | F36: =SUMPRODUCT((Koreksi_Data!$B$7:$B$2719=$A36)*ISNUMBER(Koreksi_Data!$I$7:$I$2719)*(Koreksi_Data!$H$7:$H$2719>0)) -> 70 | G36: =IFERROR(_xlfn.MINIFS(Koreksi_Data!$J$7:$J$2719,Koreksi_Data!$B$7:$B$2719,$A36,Koreksi_Data!$H$7:$H$2719,">=0"),"-") -> 0.55362319 | H36: =IFERROR(_xlfn.MAXIFS(Koreksi_Data!$J$7:$J$2719,Koreksi_Data!$B$7:$B$2719,$A36,Koreksi_Data!$H$7:$H$2719,">=0"),"-") -> 15.313408 | I36: =IFERROR(AVERAGEIFS(Koreksi_Data!$J$7:$J$2719,Koreksi_Data!$B$7:$B$2719,$A36,Koreksi_Data!$H$7:$H$2719,">=0"),"-") -> 2.3070951 | J36: =INDEX(Koreksi_Data!$J$7:$J$2719,MATCH($A36,Koreksi_Data!$B$7:$B$2719,0)+COUNTIF(Koreksi_Data!$B$7:$B$2719,$A36)-1) -> 1.375 | K36: =SUMPRODUCT((Koreksi_Data!$B$7:$B$2719=$A36)*Koreksi_Data!$H$7:$H$2719*Koreksi_Data!$T$7:$T$2719)/1000 -> 3282.831 | L36: =SUMPRODUCT((Koreksi_Data!$B$7:$B$2719=$A36)*Koreksi_Data!$K$7:$K$2719*Koreksi_Data!$T$7:$T$2719)/1000 -> 5384.4027 | M36: =IF(K36=0,"-",L36/K36-1) -> 0.64017053 | N36: =IFERROR(SUMPRODUCT((Koreksi_Data!$B$7:$B$2719=$A36)*ISNUMBER(Koreksi_Data!$I$7:$I$2719)*Koreksi_Data!$H$7:$H$2719)/SUMPRODUCT((Koreksi_Data!$B$7:$B$2719=$A36)*ISNUMBER(Koreksi_Data!$H$7:$H$2719)*Koreksi_Data!$I$7:$I$2719),"-") -> 0.68076331
A37: KKNB-1 | B37: =_xlfn.MINIFS(Koreksi_Data!$C$7:$C$2719,Koreksi_Data!$B$7:$B$2719,$A37) -> 42461 | C37: =_xlfn.MAXIFS(Koreksi_Data!$C$7:$C$2719,Koreksi_Data!$B$7:$B$2719,$A37) -> 46235 | D37: =COUNTIFS(Koreksi_Data!$B$7:$B$2719,$A37,Koreksi_Data!$H$7:$H$2719,">=0") -> 104 | E37: =COUNTIFS(Koreksi_Data!$B$7:$B$2719,$A37,Koreksi_Data!$I$7:$I$2719,">=0") -> 39 | F37: =SUMPRODUCT((Koreksi_Data!$B$7:$B$2719=$A37)*ISNUMBER(Koreksi_Data!$I$7:$I$2719)*(Koreksi_Data!$H$7:$H$2719>0)) -> 29 | G37: =IFERROR(_xlfn.MINIFS(Koreksi_Data!$J$7:$J$2719,Koreksi_Data!$B$7:$B$2719,$A37,Koreksi_Data!$H$7:$H$2719,">=0"),"-") -> 0.73360107 | H37: =IFERROR(_xlfn.MAXIFS(Koreksi_Data!$J$7:$J$2719,Koreksi_Data!$B$7:$B$2719,$A37,Koreksi_Data!$H$7:$H$2719,">=0"),"-") -> 1.7263279 | I37: =IFERROR(AVERAGEIFS(Koreksi_Data!$J$7:$J$2719,Koreksi_Data!$B$7:$B$2719,$A37,Koreksi_Data!$H$7:$H$2719,">=0"),"-") -> 1.3443061 | J37: =INDEX(Koreksi_Data!$J$7:$J$2719,MATCH($A37,Koreksi_Data!$B$7:$B$2719,0)+COUNTIF(Koreksi_Data!$B$7:$B$2719,$A37)-1) -> 1.0524968 | K37: =SUMPRODUCT((Koreksi_Data!$B$7:$B$2719=$A37)*Koreksi_Data!$H$7:$H$2719*Koreksi_Data!$T$7:$T$2719)/1000 -> 3711.896 | L37: =SUMPRODUCT((Koreksi_Data!$B$7:$B$2719=$A37)*Koreksi_Data!$K$7:$K$2719*Koreksi_Data!$T$7:$T$2719)/1000 -> 5176.1295 | M37: =IF(K37=0,"-",L37/K37-1) -> 0.3944705 | N37: =IFERROR(SUMPRODUCT((Koreksi_Data!$B$7:$B$2719=$A37)*ISNUMBER(Koreksi_Data!$I$7:$I$2719)*Koreksi_Data!$H$7:$H$2719)/SUMPRODUCT((Koreksi_Data!$B$7:$B$2719=$A37)*ISNUMBER(Koreksi_Data!$H$7:$H$2719)*Koreksi_Data!$I$7:$I$2719),"-") -> 0.77922331
... A40: KKNB-2 | B40: =_xlfn.MINIFS(Koreksi_Data!$C$7:$C$2719,Koreksi_Data!$B$7:$B$2719,$A40) -> 36281 | C40: =_xlfn.MAXIFS(Koreksi_Data!$C$7:$C$2719,Koreksi_Data!$B$7:$B$2719,$A40) -> 45748 | D40: =COUNTIFS(Koreksi_Data!$B$7:$B$2719,$A40,Koreksi_Data!$H$7:$H$2719,">=0") -> 279 | E40: =COUNTIFS(Koreksi_Data!$B$7:$B$2719,$A40,Koreksi_Data!$I$7:$I$2719,">=0") -> 55 | F40: =SUMPRODUCT((Koreksi_Data!$B$7:$B$2719=$A40)*ISNUMBER(Koreksi_Data!$I$7:$I$2719)*(Koreksi_Data!$H$7:$H$2719>0)) -> 55 | G40: =IFERROR(_xlfn.MINIFS(Koreksi_Data!$J$7:$J$2719,Koreksi_Data!$B$7:$B$2719,$A40,Koreksi_Data!$H$7:$H$2719,">=0"),"-") -> 0 | H40: =IFERROR(_xlfn.MAXIFS(Koreksi_Data!$J$7:$J$2719,Koreksi_Data!$B$7:$B$2719,$A40,Koreksi_Data!$H$7:$H$2719,">=0"),"-") -> 4.1669866 | I40: =IFERROR(AVERAGEIFS(Koreksi_Data!$J$7:$J$2719,Koreksi_Data!$B$7:$B$2719,$A40,Koreksi_Data!$H$7:$H$2719,">=0"),"-") -> 1.3557225 | J40: =INDEX(Koreksi_Data!$J$7:$J$2719,MATCH($A40,Koreksi_Data!$B$7:$B$2719,0)+COUNTIF(Koreksi_Data!$B$7:$B$2719,$A40)-1) -> 1.1625709 | K40: =SUMPRODUCT((Koreksi_Data!$B$7:$B$2719=$A40)*Koreksi_Data!$H$7:$H$2719*Koreksi_Data!$T$7:$T$2719)/1000 -> 12123.65 | L40: =SUMPRODUCT((Koreksi_Data!$B$7:$B$2719=$A40)*Koreksi_Data!$K$7:$K$2719*Koreksi_Data!$T$7:$T$2719)/1000 -> 15885.022 | M40: =IF(K40=0,"-",L40/K40-1) -> 0.31025082 | N40: =IFERROR(SUMPRODUCT((Koreksi_Data!$B$7:$B$2719=$A40)*ISNUMBER(Koreksi_Data!$I$7:$I$2719)*Koreksi_Data!$H$7:$H$2719)/SUMPRODUCT((Koreksi_Data!$B$7:$B$2719=$A40)*ISNUMBER(Koreksi_Data!$H$7:$H$2719)*Koreksi_Data!$I$7:$I$2719),"-") -> 0.80618117
A41: TOTAL LAPANGAN | K41: =SUM(K26:K40) -> 113588.88 | L41: =SUM(L26:L40) -> 191428.31 | M41: =IF(K41=0,"-",L41/K41-1) -> 0.68527329
A44: WATER (BWPD) | kumulatif dalam MBbl
A45: Sumur | B45: Awal data | C45: Akhir data | D45: Bulan Prod | E45: Bulan WT | F45: Titik koreksi | G45: Multiplier min | H45: Multiplier maks | I45: Multiplier rata-rata | J45: Multiplier terakhir | K45: Kum. Sebelum | L45: Kum. Sesudah | M45: Selisih (%) | N45: Prod/WT sebelum (bulan WT)
A46: KKA-1 | B46: =_xlfn.MINIFS(Koreksi_Data!$C$7:$C$2719,Koreksi_Data!$B$7:$B$2719,$A46) -> 37438 | C46: =_xlfn.MAXIFS(Koreksi_Data!$C$7:$C$2719,Koreksi_Data!$B$7:$B$2719,$A46) -> 46266 | D46: =COUNTIFS(Koreksi_Data!$B$7:$B$2719,$A46,Koreksi_Data!$L$7:$L$2719,">=0") -> 272 | E46: =COUNTIFS(Koreksi_Data!$B$7:$B$2719,$A46,Koreksi_Data!$M$7:$M$2719,">=0") -> 152 | F46: =SUMPRODUCT((Koreksi_Data!$B$7:$B$2719=$A46)*ISNUMBER(Koreksi_Data!$M$7:$M$2719)*(Koreksi_Data!$L$7:$L$2719>0)) -> 113 | G46: =IFERROR(_xlfn.MINIFS(Koreksi_Data!$N$7:$N$2719,Koreksi_Data!$B$7:$B$2719,$A46,Koreksi_Data!$L$7:$L$2719,">=0"),"-") -> 0 | H46: =IFERROR(_xlfn.MAXIFS(Koreksi_Data!$N$7:$N$2719,Koreksi_Data!$B$7:$B$2719,$A46,Koreksi_Data!$L$7:$L$2719,">=0"),"-") -> 5.3038674 | I46: =IFERROR(AVERAGEIFS(Koreksi_Data!$N$7:$N$2719,Koreksi_Data!$B$7:$B$2719,$A46,Koreksi_Data!$L$7:$L$2719,">=0"),"-") -> 1.063282 | J46: =INDEX(Koreksi_Data!$N$7:$N$2719,MATCH($A46,Koreksi_Data!$B$7:$B$2719,0)+COUNTIF(Koreksi_Data!$B$7:$B$2719,$A46)-1) -> 0.85274431 | K46: =SUMPRODUCT((Koreksi_Data!$B$7:$B$2719=$A46)*Koreksi_Data!$L$7:$L$2719*Koreksi_Data!$T$7:$T$2719)/1000 -> 1832.6866 | L46: =SUMPRODUCT((Koreksi_Data!$B$7:$B$2719=$A46)*Koreksi_Data!$O$7:$O$2719*Koreksi_Data!$T$7:$T$2719)/1000 -> 1703.9203 | M46: =IF(K46=0,"-",L46/K46-1) -> -0.070260967 | N46: =IFERROR(SUMPRODUCT((Koreksi_Data!$B$7:$B$2719=$A46)*ISNUMBER(Koreksi_Data!$M$7:$M$2719)*Koreksi_Data!$L$7:$L$2719)/SUMPRODUCT((Koreksi_Data!$B$7:$B$2719=$A46)*ISNUMBER(Koreksi_Data!$L$7:$L$2719)*Koreksi_Data!$M$7:$M$2719),"-") -> 1.2055243
A47: KKA-2ST2L | B47: =_xlfn.MINIFS(Koreksi_Data!$C$7:$C$2719,Koreksi_Data!$B$7:$B$2719,$A47) -> 39814 | C47: =_xlfn.MAXIFS(Koreksi_Data!$C$7:$C$2719,Koreksi_Data!$B$7:$B$2719,$A47) -> 42856 | D47: =COUNTIFS(Koreksi_Data!$B$7:$B$2719,$A47,Koreksi_Data!$L$7:$L$2719,">=0") -> 90 | E47: =COUNTIFS(Koreksi_Data!$B$7:$B$2719,$A47,Koreksi_Data!$M$7:$M$2719,">=0") -> 22 | F47: =SUMPRODUCT((Koreksi_Data!$B$7:$B$2719=$A47)*ISNUMBER(Koreksi_Data!$M$7:$M$2719)*(Koreksi_Data!$L$7:$L$2719>0)) -> 17 | G47: =IFERROR(_xlfn.MINIFS(Koreksi_Data!$N$7:$N$2719,Koreksi_Data!$B$7:$B$2719,$A47,Koreksi_Data!$L$7:$L$2719,">=0"),"-") -> 0 | H47: =IFERROR(_xlfn.MAXIFS(Koreksi_Data!$N$7:$N$2719,Koreksi_Data!$B$7:$B$2719,$A47,Koreksi_Data!$L$7:$L$2719,">=0"),"-") -> 7.3764259 | I47: =IFERROR(AVERAGEIFS(Koreksi_Data!$N$7:$N$2719,Koreksi_Data!$B$7:$B$2719,$A47,Koreksi_Data!$L$7:$L$2719,">=0"),"-") -> 1.1447789 | J47: =INDEX(Koreksi_Data!$N$7:$N$2719,MATCH($A47,Koreksi_Data!$B$7:$B$2719,0)+COUNTIF(Koreksi_Data!$B$7:$B$2719,$A47)-1) -> 1 | K47: =SUMPRODUCT((Koreksi_Data!$B$7:$B$2719=$A47)*Koreksi_Data!$L$7:$L$2719*Koreksi_Data!$T$7:$T$2719)/1000 -> 102.3092 | L47: =SUMPRODUCT((Koreksi_Data!$B$7:$B$2719=$A47)*Koreksi_Data!$O$7:$O$2719*Koreksi_Data!$T$7:$T$2719)/1000 -> 105.37328 | M47: =IF(K47=0,"-",L47/K47-1) -> 0.029949201 | N47: =IFERROR(SUMPRODUCT((Koreksi_Data!$B$7:$B$2719=$A47)*ISNUMBER(Koreksi_Data!$M$7:$M$2719)*Koreksi_Data!$L$7:$L$2719)/SUMPRODUCT((Koreksi_Data!$B$7:$B$2719=$A47)*ISNUMBER(Koreksi_Data!$L$7:$L$2719)*Koreksi_Data!$M$7:$M$2719),"-") -> 1.056237
A48: KKA-3 | B48: =_xlfn.MINIFS(Koreksi_Data!$C$7:$C$2719,Koreksi_Data!$B$7:$B$2719,$A48) -> 39845 | C48: =_xlfn.MAXIFS(Koreksi_Data!$C$7:$C$2719,Koreksi_Data!$B$7:$B$2719,$A48) -> 46266 | D48: =COUNTIFS(Koreksi_Data!$B$7:$B$2719,$A48,Koreksi_Data!$L$7:$L$2719,">=0") -> 193 | E48: =COUNTIFS(Koreksi_Data!$B$7:$B$2719,$A48,Koreksi_Data!$M$7:$M$2719,">=0") -> 78 | F48: =SUMPRODUCT((Koreksi_Data!$B$7:$B$2719=$A48)*ISNUMBER(Koreksi_Data!$M$7:$M$2719)*(Koreksi_Data!$L$7:$L$2719>0)) -> 45 | G48: =IFERROR(_xlfn.MINIFS(Koreksi_Data!$N$7:$N$2719,Koreksi_Data!$B$7:$B$2719,$A48,Koreksi_Data!$L$7:$L$2719,">=0"),"-") -> 0.092209857 | H48: =IFERROR(_xlfn.MAXIFS(Koreksi_Data!$N$7:$N$2719,Koreksi_Data!$B$7:$B$2719,$A48,Koreksi_Data!$L$7:$L$2719,">=0"),"-") -> 3.4652778 | I48: =IFERROR(AVERAGEIFS(Koreksi_Data!$N$7:$N$2719,Koreksi_Data!$B$7:$B$2719,$A48,Koreksi_Data!$L$7:$L$2719,">=0"),"-") -> 0.78459591 | J48: =INDEX(Koreksi_Data!$N$7:$N$2719,MATCH($A48,Koreksi_Data!$B$7:$B$2719,0)+COUNTIF(Koreksi_Data!$B$7:$B$2719,$A48)-1) -> 0.75362319 | K48: =SUMPRODUCT((Koreksi_Data!$B$7:$B$2719=$A48)*Koreksi_Data!$L$7:$L$2719*Koreksi_Data!$T$7:$T$2719)/1000 -> 2059.0875 | L48: =SUMPRODUCT((Koreksi_Data!$B$7:$B$2719=$A48)*Koreksi_Data!$O$7:$O$2719*Koreksi_Data!$T$7:$T$2719)/1000 -> 1657.3063 | M48: =IF(K48=0,"-",L48/K48-1) -> -0.19512585 | N48: =IFERROR(SUMPRODUCT((Koreksi_Data!$B$7:$B$2719=$A48)*ISNUMBER(Koreksi_Data!$M$7:$M$2719)*Koreksi_Data!$L$7:$L$2719)/SUMPRODUCT((Koreksi_Data!$B$7:$B$2719=$A48)*ISNUMBER(Koreksi_Data!$L$7:$L$2719)*Koreksi_Data!$M$7:$M$2719),"-") -> 1.2661824
A49: KKA-4 | B49: =_xlfn.MINIFS(Koreksi_Data!$C$7:$C$2719,Koreksi_Data!$B$7:$B$2719,$A49) -> 40210 | C49: =_xlfn.MAXIFS(Koreksi_Data!$C$7:$C$2719,Koreksi_Data!$B$7:$B$2719,$A49) -> 46113 | D49: =COUNTIFS(Koreksi_Data!$B$7:$B$2719,$A49,Koreksi_Data!$L$7:$L$2719,">=0") -> 172 | E49: =COUNTIFS(Koreksi_Data!$B$7:$B$2719,$A49,Koreksi_Data!$M$7:$M$2719,">=0") -> 92 | F49: =SUMPRODUCT((Koreksi_Data!$B$7:$B$2719=$A49)*ISNUMBER(Koreksi_Data!$M$7:$M$2719)*(Koreksi_Data!$L$7:$L$2719>0)) -> 82 | G49: =IFERROR(_xlfn.MINIFS(Koreksi_Data!$N$7:$N$2719,Koreksi_Data!$B$7:$B$2719,$A49,Koreksi_Data!$L$7:$L$2719,">=0"),"-") -> 0 | H49: =IFERROR(_xlfn.MAXIFS(Koreksi_Data!$N$7:$N$2719,Koreksi_Data!$B$7:$B$2719,$A49,Koreksi_Data!$L$7:$L$2719,">=0"),"-") -> 17.234043 | I49: =IFERROR(AVERAGEIFS(Koreksi_Data!$N$7:$N$2719,Koreksi_Data!$B$7:$B$2719,$A49,Koreksi_Data!$L$7:$L$2719,">=0"),"-") -> 0.95840013 | J49: =INDEX(Koreksi_Data!$N$7:$N$2719,MATCH($A49,Koreksi_Data!$B$7:$B$2719,0)+COUNTIF(Koreksi_Data!$B$7:$B$2719,$A49)-1) -> 0.84585366 | K49: =SUMPRODUCT((Koreksi_Data!$B$7:$B$2719=$A49)*Koreksi_Data!$L$7:$L$2719*Koreksi_Data!$T$7:$T$2719)/1000 -> 5572.9763 | L49: =SUMPRODUCT((Koreksi_Data!$B$7:$B$2719=$A49)*Koreksi_Data!$O$7:$O$2719*Koreksi_Data!$T$7:$T$2719)/1000 -> 4843.9683 | M49: =IF(K49=0,"-",L49/K49-1) -> -0.13081125 | N49: =IFERROR(SUMPRODUCT((Koreksi_Data!$B$7:$B$2719=$A49)*ISNUMBER(Koreksi_Data!$M$7:$M$2719)*Koreksi_Data!$L$7:$L$2719)/SUMPRODUCT((Koreksi_Data!$B$7:$B$2719=$A49)*ISNUMBER(Koreksi_Data!$L$7:$L$2719)*Koreksi_Data!$M$7:$M$2719),"-") -> 1.1512478
...

Sheet Grafik_Oil
A1: GRAFIK OIL PER SUMUR: PRODUKSI vs WELL TEST (kiri = sebelum, kanan = sesudah koreksi)
A2: Garis = produksi, tanda x merah = well test. Sumbu X = tanggal minimum-maksimum data prod/WT sumur tsb; sumbu Y sama di kedua grafik.
A3: KKA-1
A19: KKA-2ST2L
A35: KKA-3
A51: KKA-4
A67: KKNA-1L
A83: KKNA-1S
A99: KKNA-2
A115: KKNA-3
A131: KKNA-3ST
A147: KKNA-4
... A227: KKNB-2

Sheet Grafik_Gas
A1: GRAFIK GAS PER SUMUR: PRODUKSI vs WELL TEST (kiri = sebelum, kanan = sesudah koreksi)
A2: Garis = produksi, tanda x merah = well test. Sumbu X = tanggal minimum-maksimum data prod/WT sumur tsb; sumbu Y sama di kedua grafik.
A3: KKA-1
A19: KKA-2ST2L
A35: KKA-3
A51: KKA-4
A67: KKNA-1L
A83: KKNA-1S
A99: KKNA-2
A115: KKNA-3
A131: KKNA-3ST
A147: KKNA-4
... A227: KKNB-2

Sheet Grafik_Water
A1: GRAFIK WATER PER SUMUR: PRODUKSI vs WELL TEST (kiri = sebelum, kanan = sesudah koreksi)
A2: Garis = produksi, tanda x merah = well test. Sumbu X = tanggal minimum-maksimum data prod/WT sumur tsb; sumbu Y sama di kedua grafik.
A3: KKA-1
A19: KKA-2ST2L
A35: KKA-3
A51: KKA-4
A67: KKNA-1L
A83: KKNA-1S
A99: KKNA-2
A115: KKNA-3
A131: KKNA-3ST
A147: KKNA-4
... A227: KKNB-2

Sheet Grafik_Fluid
A1: GRAFIK FLUID PER SUMUR: PRODUKSI vs WELL TEST (kiri = sebelum, kanan = sesudah koreksi)
A2: Garis = produksi, tanda x merah = well test. Sumbu X = tanggal minimum-maksimum data prod/WT sumur tsb; sumbu Y sama di kedua grafik.
A3: KKA-1
A19: KKA-2ST2L
A35: KKA-3
A51: KKA-4
A67: KKNA-1L
A83: KKNA-1S
A99: KKNA-2
A115: KKNA-3
A131: KKNA-3ST
A147: KKNA-4
... A227: KKNB-2

Sheet Koreksi_Data
A1: DATA PRODUKSI TERKOREKSI TERHADAP WELL TEST (METODE MULTIPLIER)
A2: Biru = data input dari file sumber (sheet Rekap). Hitam = rumus. Kolom Prod/WT kosong = tidak ada data pada bulan tsb. Prod Koreksi = WT pada bulan yang ada WT (dan Prod > 0); = Prod x Multiplier pada bulan lainnya.
A3: Aturan lengkap dan asumsi ada di sheet Metode.
D5: OIL (BOPD) | H5: GAS (MCFPD) | L5: WATER (BWPD) | P5: FLUID (BFPD)
A6: Platform | B6: Well | C6: Bulan | D6: Prod | E6: WT | F6: Multiplier | G6: Prod Koreksi | H6: Prod | I6: WT | J6: Multiplier | K6: Prod Koreksi | L6: Prod | M6: WT | N6: Multiplier | O6: Prod Koreksi | P6: Prod | Q6: WT | R6: Multiplier | S6: Prod Koreksi | T6: Hari/bulan
A7: KKA | B7: KKA-1 | C7: 37438 | D7: 0 | E7: 318.25 | F7: =IF(AND(ISNUMBER(E7),D7>0),E7/D7,IF($B7=$B6,IF(F6=0,1,F6),1)) -> 1 | G7: =IF(AND(ISNUMBER(E7),D7>0),E7,D7*F7) -> 0 | H7: 0 | I7: 4573.5 | J7: =IF(AND(ISNUMBER(I7),H7>0),I7/H7,IF($B7=$B6,IF(J6=0,1,J6),1)) -> 1 | K7: =IF(AND(ISNUMBER(I7),H7>0),I7,H7*J7) -> 0 | L7: 0 | M7: 16.25 | N7: =IF(AND(ISNUMBER(M7),L7>0),M7/L7,IF($B7=$B6,IF(N6=0,1,N6),1)) -> 1 | O7: =IF(AND(ISNUMBER(M7),L7>0),M7,L7*N7) -> 0 | P7: 0 | Q7: 334.25 | R7: =IF(AND(ISNUMBER(Q7),P7>0),Q7/P7,IF($B7=$B6,IF(R6=0,1,R6),1)) -> 1 | S7: =IF(AND(ISNUMBER(Q7),P7>0),Q7,P7*R7) -> 0 | T7: =DAY(EOMONTH(C7,0)) -> 31
A8: KKA | B8: KKA-1 | C8: 37469 | D8: 552 | E8: 579.2 | F8: =IF(AND(ISNUMBER(E8),D8>0),E8/D8,IF($B8=$B7,IF(F7=0,1,F7),1)) -> 1.0492754 | G8: =IF(AND(ISNUMBER(E8),D8>0),E8,D8*F8) -> 579.2 | H8: 4076 | I8: 7357.8 | J8: =IF(AND(ISNUMBER(I8),H8>0),I8/H8,IF($B8=$B7,IF(J7=0,1,J7),1)) -> 1.8051521 | K8: =IF(AND(ISNUMBER(I8),H8>0),I8,H8*J8) -> 7357.8 | L8: 0 | M8: 16.4 | N8: =IF(AND(ISNUMBER(M8),L8>0),M8/L8,IF($B8=$B7,IF(N7=0,1,N7),1)) -> 1 | O8: =IF(AND(ISNUMBER(M8),L8>0),M8,L8*N8) -> 0 | P8: 552 | Q8: 595.6 | R8: =IF(AND(ISNUMBER(Q8),P8>0),Q8/P8,IF($B8=$B7,IF(R7=0,1,R7),1)) -> 1.0789855 | S8: =IF(AND(ISNUMBER(Q8),P8>0),Q8,P8*R8) -> 595.6 | T8: =DAY(EOMONTH(C8,0)) -> 31
A9: KKA | B9: KKA-1 | C9: 37500 | D9: 561 | F9: =IF(AND(ISNUMBER(E9),D9>0),E9/D9,IF($B9=$B8,IF(F8=0,1,F8),1)) -> 1.0492754 | G9: =IF(AND(ISNUMBER(E9),D9>0),E9,D9*F9) -> 588.64348 | H9: 4013 | J9: =IF(AND(ISNUMBER(I9),H9>0),I9/H9,IF($B9=$B8,IF(J8=0,1,J8),1)) -> 1.8051521 | K9: =IF(AND(ISNUMBER(I9),H9>0),I9,H9*J9) -> 7244.0754 | L9: 0 | N9: =IF(AND(ISNUMBER(M9),L9>0),M9/L9,IF($B9=$B8,IF(N8=0,1,N8),1)) -> 1 | O9: =IF(AND(ISNUMBER(M9),L9>0),M9,L9*N9) -> 0 | P9: 561 | R9: =IF(AND(ISNUMBER(Q9),P9>0),Q9/P9,IF($B9=$B8,IF(R8=0,1,R8),1)) -> 1.0789855 | S9: =IF(AND(ISNUMBER(Q9),P9>0),Q9,P9*R9) -> 605.31087 | T9: =DAY(EOMONTH(C9,0)) -> 30
A10: KKA | B10: KKA-1 | C10: 37530 | D10: 543 | E10: 805 | F10: =IF(AND(ISNUMBER(E10),D10>0),E10/D10,IF($B10=$B9,IF(F9=0,1,F9),1)) -> 1.4825046 | G10: =IF(AND(ISNUMBER(E10),D10>0),E10,D10*F10) -> 805 | H10: 3637 | I10: 8043 | J10: =IF(AND(ISNUMBER(I10),H10>0),I10/H10,IF($B10=$B9,IF(J9=0,1,J9),1)) -> 2.211438 | K10: =IF(AND(ISNUMBER(I10),H10>0),I10,H10*J10) -> 8043 | L10: 0 | M10: 0 | N10: =IF(AND(ISNUMBER(M10),L10>0),M10/L10,IF($B10=$B9,IF(N9=0,1,N9),1)) -> 1 | O10: =IF(AND(ISNUMBER(M10),L10>0),M10,L10*N10) -> 0 | P10: 543 | Q10: 805 | R10: =IF(AND(ISNUMBER(Q10),P10>0),Q10/P10,IF($B10=$B9,IF(R9=0,1,R9),1)) -> 1.4825046 | S10: =IF(AND(ISNUMBER(Q10),P10>0),Q10,P10*R10) -> 805 | T10: =DAY(EOMONTH(C10,0)) -> 31
A11: KKA | B11: KKA-1 | C11: 37561 | D11: 568 | F11: =IF(AND(ISNUMBER(E11),D11>0),E11/D11,IF($B11=$B10,IF(F10=0,1,F10),1)) -> 1.4825046 | G11: =IF(AND(ISNUMBER(E11),D11>0),E11,D11*F11) -> 842.06262 | H11: 4225 | J11: =IF(AND(ISNUMBER(I11),H11>0),I11/H11,IF($B11=$B10,IF(J10=0,1,J10),1)) -> 2.211438 | K11: =IF(AND(ISNUMBER(I11),H11>0),I11,H11*J11) -> 9343.3255 | L11: 0 | N11: =IF(AND(ISNUMBER(M11),L11>0),M11/L11,IF($B11=$B10,IF(N10=0,1,N10),1)) -> 1 | O11: =IF(AND(ISNUMBER(M11),L11>0),M11,L11*N11) -> 0 | P11: 568 | R11: =IF(AND(ISNUMBER(Q11),P11>0),Q11/P11,IF($B11=$B10,IF(R10=0,1,R10),1)) -> 1.4825046 | S11: =IF(AND(ISNUMBER(Q11),P11>0),Q11,P11*R11) -> 842.06262 | T11: =DAY(EOMONTH(C11,0)) -> 30
A12: KKA | B12: KKA-1 | C12: 37591 | D12: 534 | E12: 732 | F12: =IF(AND(ISNUMBER(E12),D12>0),E12/D12,IF($B12=$B11,IF(F11=0,1,F11),1)) -> 1.3707865 | G12: =IF(AND(ISNUMBER(E12),D12>0),E12,D12*F12) -> 732 | H12: 3695 | I12: 7086 | J12: =IF(AND(ISNUMBER(I12),H12>0),I12/H12,IF($B12=$B11,IF(J11=0,1,J11),1)) -> 1.9177267 | K12: =IF(AND(ISNUMBER(I12),H12>0),I12,H12*J12) -> 7086 | L12: 0 | M12: 0 | N12: =IF(AND(ISNUMBER(M12),L12>0),M12/L12,IF($B12=$B11,IF(N11=0,1,N11),1)) -> 1 | O12: =IF(AND(ISNUMBER(M12),L12>0),M12,L12*N12) -> 0 | P12: 534 | Q12: 732 | R12: =IF(AND(ISNUMBER(Q12),P12>0),Q12/P12,IF($B12=$B11,IF(R11=0,1,R11),1)) -> 1.3707865 | S12: =IF(AND(ISNUMBER(Q12),P12>0),Q12,P12*R12) -> 732 | T12: =DAY(EOMONTH(C12,0)) -> 31
A13: KKA | B13: KKA-1 | C13: 37622 | D13: 485 | E13: 636 | F13: =IF(AND(ISNUMBER(E13),D13>0),E13/D13,IF($B13=$B12,IF(F12=0,1,F12),1)) -> 1.3113402 | G13: =IF(AND(ISNUMBER(E13),D13>0),E13,D13*F13) -> 636 | H13: 4167 | I13: 8067 | J13: =IF(AND(ISNUMBER(I13),H13>0),I13/H13,IF($B13=$B12,IF(J12=0,1,J12),1)) -> 1.9359251 | K13: =IF(AND(ISNUMBER(I13),H13>0),I13,H13*J13) -> 8067 | L13: 0 | M13: 0 | N13: =IF(AND(ISNUMBER(M13),L13>0),M13/L13,IF($B13=$B12,IF(N12=0,1,N12),1)) -> 1 | O13: =IF(AND(ISNUMBER(M13),L13>0),M13,L13*N13) -> 0 | P13: 485 | Q13: 636 | R13: =IF(AND(ISNUMBER(Q13),P13>0),Q13/P13,IF($B13=$B12,IF(R12=0,1,R12),1)) -> 1.3113402 | S13: =IF(AND(ISNUMBER(Q13),P13>0),Q13,P13*R13) -> 636 | T13: =DAY(EOMONTH(C13,0)) -> 31
A14: KKA | B14: KKA-1 | C14: 37653 | D14: 613 | F14: =IF(AND(ISNUMBER(E14),D14>0),E14/D14,IF($B14=$B13,IF(F13=0,1,F13),1)) -> 1.3113402 | G14: =IF(AND(ISNUMBER(E14),D14>0),E14,D14*F14) -> 803.85155 | H14: 4042 | J14: =IF(AND(ISNUMBER(I14),H14>0),I14/H14,IF($B14=$B13,IF(J13=0,1,J13),1)) -> 1.9359251 | K14: =IF(AND(ISNUMBER(I14),H14>0),I14,H14*J14) -> 7825.0094 | L14: 0 | N14: =IF(AND(ISNUMBER(M14),L14>0),M14/L14,IF($B14=$B13,IF(N13=0,1,N13),1)) -> 1 | O14: =IF(AND(ISNUMBER(M14),L14>0),M14,L14*N14) -> 0 | P14: 613 | R14: =IF(AND(ISNUMBER(Q14),P14>0),Q14/P14,IF($B14=$B13,IF(R13=0,1,R13),1)) -> 1.3113402 | S14: =IF(AND(ISNUMBER(Q14),P14>0),Q14,P14*R14) -> 803.85155 | T14: =DAY(EOMONTH(C14,0)) -> 28
A15: KKA | B15: KKA-1 | C15: 37681 | D15: 583 | E15: 744 | F15: =IF(AND(ISNUMBER(E15),D15>0),E15/D15,IF($B15=$B14,IF(F14=0,1,F14),1)) -> 1.2761578 | G15: =IF(AND(ISNUMBER(E15),D15>0),E15,D15*F15) -> 744 | H15: 4158 | I15: 12669 | J15: =IF(AND(ISNUMBER(I15),H15>0),I15/H15,IF($B15=$B14,IF(J14=0,1,J14),1)) -> 3.0468975 | K15: =IF(AND(ISNUMBER(I15),H15>0),I15,H15*J15) -> 12669 | L15: 0 | M15: 0 | N15: =IF(AND(ISNUMBER(M15),L15>0),M15/L15,IF($B15=$B14,IF(N14=0,1,N14),1)) -> 1 | O15: =IF(AND(ISNUMBER(M15),L15>0),M15,L15*N15) -> 0 | P15: 583 | Q15: 744 | R15: =IF(AND(ISNUMBER(Q15),P15>0),Q15/P15,IF($B15=$B14,IF(R14=0,1,R14),1)) -> 1.2761578 | S15: =IF(AND(ISNUMBER(Q15),P15>0),Q15,P15*R15) -> 744 | T15: =DAY(EOMONTH(C15,0)) -> 31
A16: KKA | B16: KKA-1 | C16: 37712 | D16: 517 | F16: =IF(AND(ISNUMBER(E16),D16>0),E16/D16,IF($B16=$B15,IF(F15=0,1,F15),1)) -> 1.2761578 | G16: =IF(AND(ISNUMBER(E16),D16>0),E16,D16*F16) -> 659.77358 | H16: 9749 | J16: =IF(AND(ISNUMBER(I16),H16>0),I16/H16,IF($B16=$B15,IF(J15=0,1,J15),1)) -> 3.0468975 | K16: =IF(AND(ISNUMBER(I16),H16>0),I16,H16*J16) -> 29704.204 | L16: 0 | N16: =IF(AND(ISNUMBER(M16),L16>0),M16/L16,IF($B16=$B15,IF(N15=0,1,N15),1)) -> 1 | O16: =IF(AND(ISNUMBER(M16),L16>0),M16,L16*N16) -> 0 | P16: 517 | R16: =IF(AND(ISNUMBER(Q16),P16>0),Q16/P16,IF($B16=$B15,IF(R15=0,1,R15),1)) -> 1.2761578 | S16: =IF(AND(ISNUMBER(Q16),P16>0),Q16,P16*R16) -> 659.77358 | T16: =DAY(EOMONTH(C16,0)) -> 30
